package com.FP115.ManyEntities.BiomeGenBase.Structures;

import java.util.Random;

import com.FP115.ManyEntities.server.blocks.MEBlocks;
import net.minecraft.block.Block;
import net.minecraft.init.Blocks;
import net.minecraft.world.World;
import net.minecraft.world.biome.BiomeGenBase;

public class SkeletonDungeon{
	
public int i;
public int k;

public Object instance;

public SkeletonDungeon(){}


	public void generateSurface(World world, Random random, int i2, int k2){

int i = i2 + random.nextInt(15);
int k = k2 + random.nextInt(15);

int j = world.getHeightValue(i,k)-1;
if(world.getBiomeGenForCoords(i, k).biomeName.equals("Skeleton Biome")) {


if((random.nextInt(1000000)+1)<=100000){
boolean place = true;

if(place){
world.setBlock(i+3, j+0, k+1, MEBlocks.skeletonbrick, 0, 2);
world.setBlock(i+4, j+0, k+1, MEBlocks.skeletonbrick, 0, 2);
world.setBlock(i+5, j+0, k+1, MEBlocks.skeletonbrick, 0, 2);
world.setBlock(i+6, j+0, k+1, MEBlocks.skeletonbrick, 0, 2);
world.setBlock(i+7, j+0, k+1, MEBlocks.skeletonbrick, 0, 2);
world.setBlock(i+8, j+0, k+1, MEBlocks.skeletonbrick, 0, 2);
world.setBlock(i+9, j+0, k+1, MEBlocks.skeletonbrick, 0, 2);
world.setBlock(i+10, j+0, k+1, MEBlocks.skeletonbrick, 0, 2);
world.setBlock(i+11, j+0, k+1, MEBlocks.skeletonbrick, 0, 2);
world.setBlock(i+12, j+0, k+1, MEBlocks.skeletonbrick, 0, 2);
world.setBlock(i+13, j+0, k+1, MEBlocks.skeletonbrick, 0, 2);
world.setBlock(i+3, j+0, k+2, MEBlocks.skeletonbrick, 0, 2);
world.setBlock(i+4, j+0, k+2, Block.getBlockById(11), 0, 2);
world.setBlock(i+5, j+0, k+2, MEBlocks.skeletonbrick, 0, 2);
world.setBlock(i+6, j+0, k+2, MEBlocks.skeletonbrick, 0, 2);
world.setBlock(i+7, j+0, k+2, MEBlocks.skeletonbrick, 0, 2);
world.setBlock(i+8, j+0, k+2, MEBlocks.skeletonbrick, 0, 2);
world.setBlock(i+9, j+0, k+2, MEBlocks.skeletonbrick, 0, 2);
world.setBlock(i+10, j+0, k+2, MEBlocks.skeletonbrick, 0, 2);
world.setBlock(i+11, j+0, k+2, MEBlocks.skeletonbrick, 0, 2);
world.setBlock(i+12, j+0, k+2, Block.getBlockById(11), 0, 2);
world.setBlock(i+13, j+0, k+2, MEBlocks.skeletonbrick, 0, 2);
world.setBlock(i+3, j+0, k+3, MEBlocks.skeletonbrick, 0, 2);
world.setBlock(i+4, j+0, k+3, MEBlocks.skeletonbrick, 0, 2);
world.setBlock(i+5, j+0, k+3, MEBlocks.skeletonbrick, 0, 2);
world.setBlock(i+6, j+0, k+3, MEBlocks.skeletonbrick, 0, 2);
world.setBlock(i+7, j+0, k+3, MEBlocks.skeletonbrick, 0, 2);
world.setBlock(i+8, j+0, k+3, MEBlocks.skeletonbrick, 0, 2);
world.setBlock(i+9, j+0, k+3, MEBlocks.skeletonbrick, 0, 2);
world.setBlock(i+10, j+0, k+3, MEBlocks.skeletonbrick, 0, 2);
world.setBlock(i+11, j+0, k+3, MEBlocks.skeletonbrick, 0, 2);
world.setBlock(i+12, j+0, k+3, MEBlocks.skeletonbrick, 0, 2);
world.setBlock(i+13, j+0, k+3, MEBlocks.skeletonbrick, 0, 2);
world.setBlock(i+3, j+0, k+4, MEBlocks.skeletonbrick, 0, 2);
world.setBlock(i+4, j+0, k+4, MEBlocks.skeletonbrick, 0, 2);
world.setBlock(i+5, j+0, k+4, MEBlocks.skeletonbrick, 0, 2);
world.setBlock(i+6, j+0, k+4, MEBlocks.skeletonbrick, 0, 2);
world.setBlock(i+7, j+0, k+4, MEBlocks.skeletonbrick, 0, 2);
world.setBlock(i+8, j+0, k+4, MEBlocks.skeletonbrick, 0, 2);
world.setBlock(i+9, j+0, k+4, MEBlocks.skeletonbrick, 0, 2);
world.setBlock(i+10, j+0, k+4, MEBlocks.skeletonbrick, 0, 2);
world.setBlock(i+11, j+0, k+4, MEBlocks.skeletonbrick, 0, 2);
world.setBlock(i+12, j+0, k+4, MEBlocks.skeletonbrick, 0, 2);
world.setBlock(i+13, j+0, k+4, MEBlocks.skeletonbrick, 0, 2);
world.setBlock(i+3, j+0, k+5, MEBlocks.skeletonbrick, 0, 2);
world.setBlock(i+4, j+0, k+5, MEBlocks.skeletonbrick, 0, 2);
world.setBlock(i+5, j+0, k+5, MEBlocks.skeletonbrick, 0, 2);
world.setBlock(i+6, j+0, k+5, MEBlocks.skeletonbrick, 0, 2);
world.setBlock(i+7, j+0, k+5, MEBlocks.skeletonbrick, 0, 2);
world.setBlock(i+8, j+0, k+5, MEBlocks.skeletonbrick, 0, 2);
world.setBlock(i+9, j+0, k+5, MEBlocks.skeletonbrick, 0, 2);
world.setBlock(i+10, j+0, k+5, MEBlocks.skeletonbrick, 0, 2);
world.setBlock(i+11, j+0, k+5, MEBlocks.skeletonbrick, 0, 2);
world.setBlock(i+12, j+0, k+5, MEBlocks.skeletonbrick, 0, 2);
world.setBlock(i+13, j+0, k+5, MEBlocks.skeletonbrick, 0, 2);
world.setBlock(i+3, j+0, k+6, MEBlocks.skeletonbrick, 0, 2);
world.setBlock(i+4, j+0, k+6, MEBlocks.skeletonbrick, 0, 2);
world.setBlock(i+5, j+0, k+6, MEBlocks.skeletonbrick, 0, 2);
world.setBlock(i+6, j+0, k+6, MEBlocks.skeletonbrick, 0, 2);
world.setBlock(i+7, j+0, k+6, MEBlocks.skeletonbrick, 0, 2);
world.setBlock(i+8, j+0, k+6, MEBlocks.skeletonbrick, 0, 2);
world.setBlock(i+9, j+0, k+6, MEBlocks.skeletonbrick, 0, 2);
world.setBlock(i+10, j+0, k+6, MEBlocks.skeletonbrick, 0, 2);
world.setBlock(i+11, j+0, k+6, MEBlocks.skeletonbrick, 0, 2);
world.setBlock(i+12, j+0, k+6, MEBlocks.skeletonbrick, 0, 2);
world.setBlock(i+13, j+0, k+6, MEBlocks.skeletonbrick, 0, 2);
world.setBlock(i+3, j+0, k+7, MEBlocks.skeletonbrick, 0, 2);
world.setBlock(i+4, j+0, k+7, MEBlocks.skeletonbrick, 0, 2);
world.setBlock(i+5, j+0, k+7, MEBlocks.skeletonbrick, 0, 2);
world.setBlock(i+6, j+0, k+7, MEBlocks.skeletonbrick, 0, 2);
world.setBlock(i+7, j+0, k+7, MEBlocks.skeletonbrick, 0, 2);
world.setBlock(i+8, j+0, k+7, MEBlocks.skeletonbrick, 0, 2);
world.setBlock(i+9, j+0, k+7, MEBlocks.skeletonbrick, 0, 2);
world.setBlock(i+10, j+0, k+7, MEBlocks.skeletonbrick, 0, 2);
world.setBlock(i+11, j+0, k+7, MEBlocks.skeletonbrick, 0, 2);
world.setBlock(i+12, j+0, k+7, MEBlocks.skeletonbrick, 0, 2);
world.setBlock(i+13, j+0, k+7, MEBlocks.skeletonbrick, 0, 2);
world.setBlock(i+3, j+0, k+8, MEBlocks.skeletonbrick, 0, 2);
world.setBlock(i+4, j+0, k+8, MEBlocks.skeletonbrick, 0, 2);
world.setBlock(i+5, j+0, k+8, MEBlocks.skeletonbrick, 0, 2);
world.setBlock(i+6, j+0, k+8, MEBlocks.skeletonbrick, 0, 2);
world.setBlock(i+7, j+0, k+8, MEBlocks.skeletonbrick, 0, 2);
world.setBlock(i+8, j+0, k+8, MEBlocks.skeletonbrick, 0, 2);
world.setBlock(i+9, j+0, k+8, MEBlocks.skeletonbrick, 0, 2);
world.setBlock(i+10, j+0, k+8, MEBlocks.skeletonbrick, 0, 2);
world.setBlock(i+11, j+0, k+8, MEBlocks.skeletonbrick, 0, 2);
world.setBlock(i+12, j+0, k+8, MEBlocks.skeletonbrick, 0, 2);
world.setBlock(i+13, j+0, k+8, MEBlocks.skeletonbrick, 0, 2);
world.setBlock(i+3, j+0, k+9, MEBlocks.skeletonbrick, 0, 2);
world.setBlock(i+4, j+0, k+9, Block.getBlockById(11), 0, 2);
world.setBlock(i+5, j+0, k+9, MEBlocks.skeletonbrick, 0, 2);
world.setBlock(i+6, j+0, k+9, MEBlocks.skeletonbrick, 0, 2);
world.setBlock(i+7, j+0, k+9, MEBlocks.skeletonbrick, 0, 2);
world.setBlock(i+8, j+0, k+9, MEBlocks.skeletonbrick, 0, 2);
world.setBlock(i+9, j+0, k+9, MEBlocks.skeletonbrick, 0, 2);
world.setBlock(i+10, j+0, k+9, MEBlocks.skeletonbrick, 0, 2);
world.setBlock(i+11, j+0, k+9, MEBlocks.skeletonbrick, 0, 2);
world.setBlock(i+12, j+0, k+9, Block.getBlockById(11), 0, 2);
world.setBlock(i+13, j+0, k+9, MEBlocks.skeletonbrick, 0, 2);
world.setBlock(i+3, j+0, k+10, MEBlocks.skeletonbrick, 0, 2);
world.setBlock(i+4, j+0, k+10, MEBlocks.skeletonbrick, 0, 2);
world.setBlock(i+5, j+0, k+10, MEBlocks.skeletonbrick, 0, 2);
world.setBlock(i+6, j+0, k+10, MEBlocks.skeletonbrick, 0, 2);
world.setBlock(i+7, j+0, k+10, MEBlocks.skeletonbrick, 0, 2);
world.setBlock(i+8, j+0, k+10, MEBlocks.skeletonbrick, 0, 2);
world.setBlock(i+9, j+0, k+10, MEBlocks.skeletonbrick, 0, 2);
world.setBlock(i+10, j+0, k+10, MEBlocks.skeletonbrick, 0, 2);
world.setBlock(i+11, j+0, k+10, MEBlocks.skeletonbrick, 0, 2);
world.setBlock(i+12, j+0, k+10, MEBlocks.skeletonbrick, 0, 2);
world.setBlock(i+13, j+0, k+10, MEBlocks.skeletonbrick, 0, 2);
world.setBlock(i+6, j+0, k+11, MEBlocks.skeletonbrick, 0, 2);
world.setBlock(i+7, j+0, k+11, MEBlocks.skeletonbrick, 0, 2);
world.setBlock(i+8, j+0, k+11, MEBlocks.skeletonbrick, 0, 2);
world.setBlock(i+9, j+0, k+11, MEBlocks.skeletonbrick, 0, 2);
world.setBlock(i+4, j+0, k+12, MEBlocks.skeletonbrick, 0, 2);
world.setBlock(i+5, j+0, k+12, MEBlocks.skeletonbrick, 0, 2);
world.setBlock(i+6, j+0, k+12, MEBlocks.skeletonbrick, 0, 2);
world.setBlock(i+7, j+0, k+12, MEBlocks.skeletonbrick, 0, 2);
world.setBlock(i+8, j+0, k+12, MEBlocks.skeletonbrick, 0, 2);
world.setBlock(i+9, j+0, k+12, MEBlocks.skeletonbrick, 0, 2);
world.setBlock(i+10, j+0, k+12, MEBlocks.skeletonbrick, 0, 2);
world.setBlock(i+11, j+0, k+12, MEBlocks.skeletonbrick, 0, 2);
world.setBlock(i+4, j+0, k+13, MEBlocks.skeletonbrick, 0, 2);
world.setBlock(i+5, j+0, k+13, Block.getBlockById(11), 8, 2);
world.setBlock(i+6, j+0, k+13, MEBlocks.skeletonbrick, 0, 2);
world.setBlock(i+7, j+0, k+13, MEBlocks.skeletonbrick, 0, 2);
world.setBlock(i+8, j+0, k+13, MEBlocks.skeletonbrick, 0, 2);
world.setBlock(i+9, j+0, k+13, MEBlocks.skeletonbrick, 0, 2);
world.setBlock(i+10, j+0, k+13, Block.getBlockById(11), 8, 2);
world.setBlock(i+11, j+0, k+13, MEBlocks.skeletonbrick, 0, 2);
world.setBlock(i+4, j+0, k+14, MEBlocks.skeletonbrick, 0, 2);
world.setBlock(i+5, j+0, k+14, MEBlocks.skeletonbrick, 0, 2);
world.setBlock(i+6, j+0, k+14, MEBlocks.skeletonbrick, 0, 2);
world.setBlock(i+7, j+0, k+14, MEBlocks.skeletonbrick, 0, 2);
world.setBlock(i+8, j+0, k+14, MEBlocks.skeletonbrick, 0, 2);
world.setBlock(i+9, j+0, k+14, MEBlocks.skeletonbrick, 0, 2);
world.setBlock(i+10, j+0, k+14, MEBlocks.skeletonbrick, 0, 2);
world.setBlock(i+11, j+0, k+14, MEBlocks.skeletonbrick, 0, 2);
world.setBlock(i+6, j+0, k+15, MEBlocks.skeletonbrick, 0, 2);
world.setBlock(i+7, j+0, k+15, MEBlocks.skeletonbrick, 0, 2);
world.setBlock(i+8, j+0, k+15, MEBlocks.skeletonbrick, 0, 2);
world.setBlock(i+9, j+0, k+15, MEBlocks.skeletonbrick, 0, 2);
world.setBlock(i+6, j+0, k+16, MEBlocks.skeletonbrick, 0, 2);
world.setBlock(i+7, j+0, k+16, MEBlocks.skeletonbrick, 0, 2);
world.setBlock(i+8, j+0, k+16, MEBlocks.skeletonbrick, 0, 2);
world.setBlock(i+9, j+0, k+16, MEBlocks.skeletonbrick, 0, 2);
world.setBlock(i+6, j+0, k+17, MEBlocks.skeletonbrick, 0, 2);
world.setBlock(i+7, j+0, k+17, MEBlocks.skeletonbrick, 0, 2);
world.setBlock(i+8, j+0, k+17, MEBlocks.skeletonbrick, 0, 2);
world.setBlock(i+9, j+0, k+17, MEBlocks.skeletonbrick, 0, 2);
world.setBlock(i+6, j+0, k+18, MEBlocks.skeletonbrick, 0, 2);
world.setBlock(i+7, j+0, k+18, MEBlocks.skeletonbrick, 0, 2);
world.setBlock(i+8, j+0, k+18, MEBlocks.skeletonbrick, 0, 2);
world.setBlock(i+9, j+0, k+18, MEBlocks.skeletonbrick, 0, 2);
world.setBlock(i+7, j+0, k+19, MEBlocks.skeletonbrick, 0, 2);
world.setBlock(i+8, j+0, k+19, MEBlocks.skeletonbrick, 0, 2);
world.setBlock(i+3, j+1, k+1, MEBlocks.skeletonbrick, 0, 2);
world.setBlock(i+4, j+1, k+1, MEBlocks.skeletonbrick, 0, 2);
world.setBlock(i+5, j+1, k+1, MEBlocks.skeletonbrick, 0, 2);
world.setBlock(i+6, j+1, k+1, MEBlocks.skeletonbrick, 0, 2);
world.setBlock(i+7, j+1, k+1, MEBlocks.skeletonbrick, 0, 2);
world.setBlock(i+8, j+1, k+1, MEBlocks.skeletonbrick, 0, 2);
world.setBlock(i+9, j+1, k+1, MEBlocks.skeletonbrick, 0, 2);
world.setBlock(i+10, j+1, k+1, MEBlocks.skeletonbrick, 0, 2);
world.setBlock(i+11, j+1, k+1, MEBlocks.skeletonbrick, 0, 2);
world.setBlock(i+12, j+1, k+1, MEBlocks.skeletonbrick, 0, 2);
world.setBlock(i+13, j+1, k+1, MEBlocks.skeletonbrick, 0, 2);
world.setBlock(i+3, j+1, k+2, MEBlocks.skeletonbrick, 0, 2);
world.setBlock(i+5, j+1, k+2, MEBlocks.skeletonbrick, 0, 2);
world.setBlock(i+7, j+1, k+2, Block.getBlockById(25), 0, 2);
world.setBlock(i+8, j+1, k+2, Block.getBlockById(25), 0, 2);
world.setBlock(i+9, j+1, k+2, Block.getBlockById(65), 3, 2);
world.setBlock(i+11, j+1, k+2, MEBlocks.skeletonbrick, 0, 2);
world.setBlock(i+13, j+1, k+2, MEBlocks.skeletonbrick, 0, 2);
world.setBlock(i+3, j+1, k+3, MEBlocks.skeletonbrick, 0, 2);
world.setBlock(i+4, j+1, k+3, MEBlocks.skeletonbrick, 0, 2);
world.setBlock(i+12, j+1, k+3, MEBlocks.skeletonbrick, 0, 2);
world.setBlock(i+13, j+1, k+3, MEBlocks.skeletonbrick, 0, 2);
world.setBlock(i+3, j+1, k+4, MEBlocks.skeletonbrick, 0, 2);
world.setBlock(i+13, j+1, k+4, MEBlocks.skeletonbrick, 0, 2);
world.setBlock(i+3, j+1, k+5, MEBlocks.skeletonbrick, 0, 2);
world.setBlock(i+4, j+1, k+5, Block.getBlockById(25), 0, 2);
world.setBlock(i+12, j+1, k+5, Block.getBlockById(25), 0, 2);
world.setBlock(i+13, j+1, k+5, MEBlocks.skeletonbrick, 0, 2);
world.setBlock(i+3, j+1, k+6, MEBlocks.skeletonbrick, 0, 2);
world.setBlock(i+4, j+1, k+6, Block.getBlockById(25), 0, 2);
world.setBlock(i+12, j+1, k+6, Block.getBlockById(25), 0, 2);
world.setBlock(i+13, j+1, k+6, MEBlocks.skeletonbrick, 0, 2);
world.setBlock(i+3, j+1, k+7, MEBlocks.skeletonbrick, 0, 2);
world.setBlock(i+13, j+1, k+7, MEBlocks.skeletonbrick, 0, 2);
world.setBlock(i+3, j+1, k+8, MEBlocks.skeletonbrick, 0, 2);
world.setBlock(i+4, j+1, k+8, MEBlocks.skeletonbrick, 0, 2);
world.setBlock(i+12, j+1, k+8, MEBlocks.skeletonbrick, 0, 2);
world.setBlock(i+13, j+1, k+8, MEBlocks.skeletonbrick, 0, 2);
world.setBlock(i+3, j+1, k+9, MEBlocks.skeletonbrick, 0, 2);
world.setBlock(i+5, j+1, k+9, MEBlocks.skeletonbrick, 0, 2);
world.setBlock(i+11, j+1, k+9, MEBlocks.skeletonbrick, 0, 2);
world.setBlock(i+13, j+1, k+9, MEBlocks.skeletonbrick, 0, 2);
world.setBlock(i+3, j+1, k+10, MEBlocks.skeletonbrick, 0, 2);
world.setBlock(i+4, j+1, k+10, MEBlocks.skeletonbrick, 0, 2);
world.setBlock(i+5, j+1, k+10, MEBlocks.skeletonbrick, 0, 2);
world.setBlock(i+6, j+1, k+10, MEBlocks.skeletonbrick, 0, 2);
world.setBlock(i+7, j+1, k+10, Block.getBlockById(71), 3, 2);
world.setBlock(i+8, j+1, k+10, Block.getBlockById(71), 3, 2);
world.setBlock(i+9, j+1, k+10, MEBlocks.skeletonbrick, 0, 2);
world.setBlock(i+10, j+1, k+10, MEBlocks.skeletonbrick, 0, 2);
world.setBlock(i+11, j+1, k+10, MEBlocks.skeletonbrick, 0, 2);
world.setBlock(i+12, j+1, k+10, MEBlocks.skeletonbrick, 0, 2);
world.setBlock(i+13, j+1, k+10, MEBlocks.skeletonbrick, 0, 2);
world.setBlock(i+6, j+1, k+11, MEBlocks.skeletonbrick, 0, 2);
world.setBlock(i+7, j+1, k+11, Block.getBlockById(70), 0, 2);
world.setBlock(i+8, j+1, k+11, Block.getBlockById(70), 0, 2);
world.setBlock(i+9, j+1, k+11, MEBlocks.skeletonbrick, 0, 2);
world.setBlock(i+4, j+1, k+12, MEBlocks.skeletonbrick, 0, 2);
world.setBlock(i+5, j+1, k+12, MEBlocks.skeletonbrick, 0, 2);
world.setBlock(i+6, j+1, k+12, MEBlocks.skeletonbrick, 0, 2);
world.setBlock(i+9, j+1, k+12, MEBlocks.skeletonbrick, 0, 2);
world.setBlock(i+10, j+1, k+12, MEBlocks.skeletonbrick, 0, 2);
world.setBlock(i+11, j+1, k+12, MEBlocks.skeletonbrick, 0, 2);
world.setBlock(i+4, j+1, k+13, MEBlocks.skeletonbrick, 0, 2);
world.setBlock(i+5, j+1, k+13, Block.getBlockById(11), 8, 2);
world.setBlock(i+6, j+1, k+13, MEBlocks.skeletonbars, 0, 2);
world.setBlock(i+9, j+1, k+13, MEBlocks.skeletonbars, 0, 2);
world.setBlock(i+10, j+1, k+13, Block.getBlockById(11), 8, 2);
world.setBlock(i+11, j+1, k+13, MEBlocks.skeletonbrick, 0, 2);
world.setBlock(i+4, j+1, k+14, MEBlocks.skeletonbrick, 0, 2);
world.setBlock(i+5, j+1, k+14, MEBlocks.skeletonbrick, 0, 2);
world.setBlock(i+6, j+1, k+14, MEBlocks.skeletonbrick, 0, 2);
world.setBlock(i+9, j+1, k+14, MEBlocks.skeletonbrick, 0, 2);
world.setBlock(i+10, j+1, k+14, MEBlocks.skeletonbrick, 0, 2);
world.setBlock(i+11, j+1, k+14, MEBlocks.skeletonbrick, 0, 2);
world.setBlock(i+6, j+1, k+15, MEBlocks.skeletonbrick, 0, 2);
world.setBlock(i+9, j+1, k+15, MEBlocks.skeletonbrick, 0, 2);
world.setBlock(i+6, j+1, k+16, MEBlocks.skeletonbrick, 0, 2);
world.setBlock(i+7, j+1, k+16, Block.getBlockById(71), 3, 2);
world.setBlock(i+8, j+1, k+16, Block.getBlockById(71), 3, 2);
world.setBlock(i+9, j+1, k+16, MEBlocks.skeletonbrick, 0, 2);
world.setBlock(i+6, j+1, k+17, MEBlocks.skeletonbrick, 0, 2);
world.setBlock(i+7, j+1, k+17, Block.getBlockById(70), 0, 2);
world.setBlock(i+8, j+1, k+17, Block.getBlockById(70), 0, 2);
world.setBlock(i+9, j+1, k+17, MEBlocks.skeletonbrick, 0, 2);
world.setBlock(i+6, j+1, k+18, MEBlocks.skeletonbrick, 0, 2);
world.setBlock(i+9, j+1, k+18, MEBlocks.skeletonbrick, 0, 2);
world.setBlock(i+3, j+2, k+1, MEBlocks.skeletonbrick, 0, 2);
world.setBlock(i+4, j+2, k+1, MEBlocks.skeletonbrick, 0, 2);
world.setBlock(i+5, j+2, k+1, MEBlocks.skeletonbrick, 0, 2);
world.setBlock(i+6, j+2, k+1, MEBlocks.skeletonbrick, 0, 2);
world.setBlock(i+7, j+2, k+1, MEBlocks.skeletonbrick, 0, 2);
world.setBlock(i+8, j+2, k+1, MEBlocks.skeletonbrick, 0, 2);
world.setBlock(i+9, j+2, k+1, MEBlocks.skeletonbrick, 0, 2);
world.setBlock(i+10, j+2, k+1, MEBlocks.skeletonbrick, 0, 2);
world.setBlock(i+11, j+2, k+1, MEBlocks.skeletonbrick, 0, 2);
world.setBlock(i+12, j+2, k+1, MEBlocks.skeletonbrick, 0, 2);
world.setBlock(i+13, j+2, k+1, MEBlocks.skeletonbrick, 0, 2);
world.setBlock(i+3, j+2, k+2, MEBlocks.skeletonbrick, 0, 2);
world.setBlock(i+5, j+2, k+2, MEBlocks.skeletonbrick, 0, 2);
world.setBlock(i+9, j+2, k+2, Block.getBlockById(65), 3, 2);
world.setBlock(i+11, j+2, k+2, MEBlocks.skeletonbrick, 0, 2);
world.setBlock(i+13, j+2, k+2, MEBlocks.skeletonbrick, 0, 2);
world.setBlock(i+3, j+2, k+3, MEBlocks.skeletonbrick, 0, 2);
world.setBlock(i+4, j+2, k+3, MEBlocks.skeletonbrick, 0, 2);
world.setBlock(i+12, j+2, k+3, MEBlocks.skeletonbrick, 0, 2);
world.setBlock(i+13, j+2, k+3, MEBlocks.skeletonbrick, 0, 2);
world.setBlock(i+3, j+2, k+4, MEBlocks.skeletonbrick, 0, 2);
world.setBlock(i+13, j+2, k+4, MEBlocks.skeletonbrick, 0, 2);
world.setBlock(i+3, j+2, k+5, MEBlocks.skeletonbrick, 0, 2);
world.setBlock(i+13, j+2, k+5, MEBlocks.skeletonbrick, 0, 2);
world.setBlock(i+3, j+2, k+6, MEBlocks.skeletonbrick, 0, 2);
world.setBlock(i+13, j+2, k+6, MEBlocks.skeletonbrick, 0, 2);
world.setBlock(i+3, j+2, k+7, MEBlocks.skeletonbrick, 0, 2);
world.setBlock(i+13, j+2, k+7, MEBlocks.skeletonbrick, 0, 2);
world.setBlock(i+3, j+2, k+8, MEBlocks.skeletonbrick, 0, 2);
world.setBlock(i+4, j+2, k+8, MEBlocks.skeletonbrick, 0, 2);
world.setBlock(i+12, j+2, k+8, MEBlocks.skeletonbrick, 0, 2);
world.setBlock(i+13, j+2, k+8, MEBlocks.skeletonbrick, 0, 2);
world.setBlock(i+3, j+2, k+9, MEBlocks.skeletonbrick, 0, 2);
world.setBlock(i+5, j+2, k+9, MEBlocks.skeletonbrick, 0, 2);
world.setBlock(i+11, j+2, k+9, MEBlocks.skeletonbrick, 0, 2);
world.setBlock(i+13, j+2, k+9, MEBlocks.skeletonbrick, 0, 2);
world.setBlock(i+3, j+2, k+10, MEBlocks.skeletonbrick, 0, 2);
world.setBlock(i+4, j+2, k+10, MEBlocks.skeletonbrick, 0, 2);
world.setBlock(i+5, j+2, k+10, MEBlocks.skeletonbrick, 0, 2);
world.setBlock(i+6, j+2, k+10, MEBlocks.skeletonbrick, 0, 2);
world.setBlock(i+7, j+2, k+10, Block.getBlockById(71), 8, 2);
world.setBlock(i+8, j+2, k+10, Block.getBlockById(71), 9, 2);
world.setBlock(i+9, j+2, k+10, MEBlocks.skeletonbrick, 0, 2);
world.setBlock(i+10, j+2, k+10, MEBlocks.skeletonbrick, 0, 2);
world.setBlock(i+11, j+2, k+10, MEBlocks.skeletonbrick, 0, 2);
world.setBlock(i+12, j+2, k+10, MEBlocks.skeletonbrick, 0, 2);
world.setBlock(i+13, j+2, k+10, MEBlocks.skeletonbrick, 0, 2);
world.setBlock(i+6, j+2, k+11, MEBlocks.skeletonbrick, 0, 2);
world.setBlock(i+9, j+2, k+11, MEBlocks.skeletonbrick, 0, 2);

world.setBlock(i+4, j+2, k+12, MEBlocks.skeletonbrick, 0, 2);
world.setBlock(i+5, j+2, k+12, MEBlocks.skeletonbars, 0, 2);
world.setBlock(i+6, j+2, k+12, MEBlocks.skeletonbrick, 0, 2);
world.setBlock(i+9, j+2, k+12, MEBlocks.skeletonbrick, 0, 2);
world.setBlock(i+10, j+2, k+12, MEBlocks.skeletonbars, 0, 2);
world.setBlock(i+11, j+2, k+12, MEBlocks.skeletonbrick, 0, 2);
world.setBlock(i+4, j+2, k+13, MEBlocks.skeletonbars, 0, 2);
world.setBlock(i+5, j+2, k+13, Block.getBlockById(11), 8, 2);
world.setBlock(i+6, j+2, k+13, MEBlocks.skeletonbars, 0, 2);
world.setBlock(i+9, j+2, k+13, MEBlocks.skeletonbars, 0, 2);
world.setBlock(i+10, j+2, k+13, Block.getBlockById(11), 8, 2);
world.setBlock(i+11, j+2, k+13, MEBlocks.skeletonbars, 0, 2);
world.setBlock(i+4, j+2, k+14, MEBlocks.skeletonbrick, 0, 2);
world.setBlock(i+5, j+2, k+14, MEBlocks.skeletonbars, 0, 2);
world.setBlock(i+6, j+2, k+14, MEBlocks.skeletonbrick, 0, 2);
world.setBlock(i+9, j+2, k+14, MEBlocks.skeletonbrick, 0, 2);
world.setBlock(i+10, j+2, k+14, MEBlocks.skeletonbars, 0, 2);
world.setBlock(i+11, j+2, k+14, MEBlocks.skeletonbrick, 0, 2);
world.setBlock(i+6, j+2, k+15, MEBlocks.skeletonbrick, 0, 2);
world.setBlock(i+9, j+2, k+15, MEBlocks.skeletonbrick, 0, 2);
world.setBlock(i+6, j+2, k+16, MEBlocks.skeletonbrick, 0, 2);
world.setBlock(i+7, j+2, k+16, Block.getBlockById(71), 8, 2);
world.setBlock(i+8, j+2, k+16, Block.getBlockById(71), 9, 2);
world.setBlock(i+9, j+2, k+16, MEBlocks.skeletonbrick, 0, 2);
world.setBlock(i+6, j+2, k+17, MEBlocks.skeletonbrick, 0, 2);
world.setBlock(i+9, j+2, k+17, MEBlocks.skeletonbrick, 0, 2);
world.setBlock(i+6, j+2, k+18, MEBlocks.skeletonbrick, 0, 2);
world.setBlock(i+9, j+2, k+18, MEBlocks.skeletonbrick, 0, 2);
world.setBlock(i+3, j+3, k+1, MEBlocks.skeletonbrick, 0, 2);
world.setBlock(i+4, j+3, k+1, MEBlocks.skeletonbrick, 0, 2);
world.setBlock(i+5, j+3, k+1, MEBlocks.skeletonbrick, 0, 2);
world.setBlock(i+6, j+3, k+1, MEBlocks.skeletonbrick, 0, 2);
world.setBlock(i+7, j+3, k+1, MEBlocks.skeletonbrick, 0, 2);
world.setBlock(i+8, j+3, k+1, MEBlocks.skeletonbrick, 0, 2);
world.setBlock(i+9, j+3, k+1, MEBlocks.skeletonbrick, 0, 2);
world.setBlock(i+10, j+3, k+1, MEBlocks.skeletonbrick, 0, 2);
world.setBlock(i+11, j+3, k+1, MEBlocks.skeletonbrick, 0, 2);
world.setBlock(i+12, j+3, k+1, MEBlocks.skeletonbrick, 0, 2);
world.setBlock(i+13, j+3, k+1, MEBlocks.skeletonbrick, 0, 2);
world.setBlock(i+3, j+3, k+2, MEBlocks.skeletonbrick, 0, 2);
world.setBlock(i+5, j+3, k+2, MEBlocks.skeletonbrick, 0, 2);
world.setBlock(i+9, j+3, k+2, Block.getBlockById(65), 3, 2);
world.setBlock(i+11, j+3, k+2, MEBlocks.skeletonbrick, 0, 2);
world.setBlock(i+13, j+3, k+2, MEBlocks.skeletonbrick, 0, 2);
world.setBlock(i+3, j+3, k+3, MEBlocks.skeletonbrick, 0, 2);
world.setBlock(i+4, j+3, k+3, MEBlocks.skeletonbrick, 0, 2);
world.setBlock(i+12, j+3, k+3, MEBlocks.skeletonbrick, 0, 2);
world.setBlock(i+13, j+3, k+3, MEBlocks.skeletonbrick, 0, 2);
world.setBlock(i+3, j+3, k+4, MEBlocks.skeletonbrick, 0, 2);
world.setBlock(i+13, j+3, k+4, MEBlocks.skeletonbrick, 0, 2);
world.setBlock(i+3, j+3, k+5, MEBlocks.skeletonbrick, 0, 2);
world.setBlock(i+13, j+3, k+5, MEBlocks.skeletonbrick, 0, 2);
world.setBlock(i+3, j+3, k+6, MEBlocks.skeletonbrick, 0, 2);
world.setBlock(i+13, j+3, k+6, MEBlocks.skeletonbrick, 0, 2);
world.setBlock(i+3, j+3, k+7, MEBlocks.skeletonbrick, 0, 2);
world.setBlock(i+13, j+3, k+7, MEBlocks.skeletonbrick, 0, 2);
world.setBlock(i+3, j+3, k+8, MEBlocks.skeletonbrick, 0, 2);
world.setBlock(i+4, j+3, k+8, MEBlocks.skeletonbrick, 0, 2);
world.setBlock(i+12, j+3, k+8, MEBlocks.skeletonbrick, 0, 2);
world.setBlock(i+13, j+3, k+8, MEBlocks.skeletonbrick, 0, 2);
world.setBlock(i+3, j+3, k+9, MEBlocks.skeletonbrick, 0, 2);
world.setBlock(i+5, j+3, k+9, MEBlocks.skeletonbrick, 0, 2);
world.setBlock(i+11, j+3, k+9, MEBlocks.skeletonbrick, 0, 2);
world.setBlock(i+13, j+3, k+9, MEBlocks.skeletonbrick, 0, 2);
world.setBlock(i+3, j+3, k+10, MEBlocks.skeletonbrick, 0, 2);
world.setBlock(i+4, j+3, k+10, MEBlocks.skeletonbrick, 0, 2);
world.setBlock(i+5, j+3, k+10, MEBlocks.skeletonbrick, 0, 2);
world.setBlock(i+6, j+3, k+10, MEBlocks.skeletonbrick, 0, 2);
world.setBlock(i+7, j+3, k+10, MEBlocks.skeletonbrick, 0, 2);
world.setBlock(i+8, j+3, k+10, MEBlocks.skeletonbrick, 0, 2);
world.setBlock(i+9, j+3, k+10, MEBlocks.skeletonbrick, 0, 2);
world.setBlock(i+10, j+3, k+10, MEBlocks.skeletonbrick, 0, 2);
world.setBlock(i+11, j+3, k+10, MEBlocks.skeletonbrick, 0, 2);
world.setBlock(i+12, j+3, k+10, MEBlocks.skeletonbrick, 0, 2);
world.setBlock(i+13, j+3, k+10, MEBlocks.skeletonbrick, 0, 2);
world.setBlock(i+6, j+3, k+11, MEBlocks.skeletonbrick, 0, 2);
world.setBlock(i+7, j+3, k+11, MEBlocks.skeletonbrick, 0, 2);
world.setBlock(i+8, j+3, k+11, MEBlocks.skeletonbrick, 0, 2);
world.setBlock(i+9, j+3, k+11, MEBlocks.skeletonbrick, 0, 2);

world.setBlock(i+4, j+3, k+12, MEBlocks.skeletonbrick, 0, 2);
world.setBlock(i+5, j+3, k+12, MEBlocks.skeletonbrick, 0, 2);
world.setBlock(i+6, j+3, k+12, MEBlocks.skeletonbrick, 0, 2);
world.setBlock(i+7, j+3, k+12, MEBlocks.skeletonbrick, 0, 2);
world.setBlock(i+8, j+3, k+12, MEBlocks.skeletonbrick, 0, 2);
world.setBlock(i+9, j+3, k+12, MEBlocks.skeletonbrick, 0, 2);
world.setBlock(i+10, j+3, k+12, MEBlocks.skeletonbrick, 0, 2);
world.setBlock(i+11, j+3, k+12, MEBlocks.skeletonbrick, 0, 2);
world.setBlock(i+4, j+3, k+13, MEBlocks.skeletonbrick, 0, 2);
world.setBlock(i+5, j+3, k+13, Block.getBlockById(11), 0, 2);
world.setBlock(i+6, j+3, k+13, MEBlocks.skeletonbrick, 0, 2);
world.setBlock(i+7, j+3, k+13, MEBlocks.skeletonbrick, 0, 2);
world.setBlock(i+8, j+3, k+13, MEBlocks.skeletonbrick, 0, 2);
world.setBlock(i+9, j+3, k+13, MEBlocks.skeletonbrick, 0, 2);
world.setBlock(i+10, j+3, k+13, Block.getBlockById(11), 0, 2);
world.setBlock(i+11, j+3, k+13, MEBlocks.skeletonbrick, 0, 2);
world.setBlock(i+4, j+3, k+14, MEBlocks.skeletonbrick, 0, 2);
world.setBlock(i+5, j+3, k+14, MEBlocks.skeletonbrick, 0, 2);
world.setBlock(i+6, j+3, k+14, MEBlocks.skeletonbrick, 0, 2);
world.setBlock(i+7, j+3, k+14, MEBlocks.skeletonbrick, 0, 2);
world.setBlock(i+8, j+3, k+14, MEBlocks.skeletonbrick, 0, 2);
world.setBlock(i+9, j+3, k+14, MEBlocks.skeletonbrick, 0, 2);
world.setBlock(i+10, j+3, k+14, MEBlocks.skeletonbrick, 0, 2);
world.setBlock(i+11, j+3, k+14, MEBlocks.skeletonbrick, 0, 2);
world.setBlock(i+6, j+3, k+15, MEBlocks.skeletonbrick, 0, 2);
world.setBlock(i+7, j+3, k+15, MEBlocks.skeletonbrick, 0, 2);
world.setBlock(i+8, j+3, k+15, MEBlocks.skeletonbrick, 0, 2);
world.setBlock(i+9, j+3, k+15, MEBlocks.skeletonbrick, 0, 2);
world.setBlock(i+6, j+3, k+16, MEBlocks.skeletonbrick, 0, 2);
world.setBlock(i+7, j+3, k+16, MEBlocks.skeletonbrick, 0, 2);
world.setBlock(i+8, j+3, k+16, MEBlocks.skeletonbrick, 0, 2);
world.setBlock(i+9, j+3, k+16, MEBlocks.skeletonbrick, 0, 2);
world.setBlock(i+6, j+3, k+17, MEBlocks.skeletonbrick, 0, 2);
world.setBlock(i+7, j+3, k+17, MEBlocks.skeletonbrick, 0, 2);
world.setBlock(i+8, j+3, k+17, MEBlocks.skeletonbrick, 0, 2);
world.setBlock(i+9, j+3, k+17, MEBlocks.skeletonbrick, 0, 2);
world.setBlock(i+6, j+3, k+18, MEBlocks.skeletonbrick, 0, 2);
world.setBlock(i+7, j+3, k+18, MEBlocks.skeletonbrick, 0, 2);
world.setBlock(i+8, j+3, k+18, MEBlocks.skeletonbrick, 0, 2);
world.setBlock(i+9, j+3, k+18, MEBlocks.skeletonbrick, 0, 2);
world.setBlock(i+3, j+4, k+1, MEBlocks.skeletonbrick, 0, 2);
world.setBlock(i+4, j+4, k+1, MEBlocks.skeletonbrick, 0, 2);
world.setBlock(i+5, j+4, k+1, MEBlocks.skeletonbrick, 0, 2);
world.setBlock(i+6, j+4, k+1, MEBlocks.skeletonbrick, 0, 2);
world.setBlock(i+7, j+4, k+1, MEBlocks.skeletonbrick, 0, 2);
world.setBlock(i+8, j+4, k+1, MEBlocks.skeletonbrick, 0, 2);
world.setBlock(i+9, j+4, k+1, MEBlocks.skeletonbrick, 0, 2);
world.setBlock(i+10, j+4, k+1, MEBlocks.skeletonbrick, 0, 2);
world.setBlock(i+11, j+4, k+1, MEBlocks.skeletonbrick, 0, 2);
world.setBlock(i+12, j+4, k+1, MEBlocks.skeletonbrick, 0, 2);
world.setBlock(i+13, j+4, k+1, MEBlocks.skeletonbrick, 0, 2);
world.setBlock(i+3, j+4, k+2, MEBlocks.skeletonbrick, 0, 2);
world.setBlock(i+9, j+4, k+2, Block.getBlockById(65), 3, 2);
world.setBlock(i+13, j+4, k+2, MEBlocks.skeletonbrick, 0, 2);
world.setBlock(i+3, j+4, k+3, MEBlocks.skeletonbrick, 0, 2);
world.setBlock(i+13, j+4, k+3, MEBlocks.skeletonbrick, 0, 2);
world.setBlock(i+3, j+4, k+4, MEBlocks.skeletonbrick, 0, 2);
world.setBlock(i+13, j+4, k+4, MEBlocks.skeletonbrick, 0, 2);
world.setBlock(i+3, j+4, k+5, MEBlocks.skeletonbrick, 0, 2);
world.setBlock(i+13, j+4, k+5, MEBlocks.skeletonbrick, 0, 2);
world.setBlock(i+3, j+4, k+6, MEBlocks.skeletonbrick, 0, 2);
world.setBlock(i+13, j+4, k+6, MEBlocks.skeletonbrick, 0, 2);
world.setBlock(i+3, j+4, k+7, MEBlocks.skeletonbrick, 0, 2);
world.setBlock(i+13, j+4, k+7, MEBlocks.skeletonbrick, 0, 2);
world.setBlock(i+3, j+4, k+8, MEBlocks.skeletonbrick, 0, 2);
world.setBlock(i+13, j+4, k+8, MEBlocks.skeletonbrick, 0, 2);
world.setBlock(i+3, j+4, k+9, MEBlocks.skeletonbrick, 0, 2);
world.setBlock(i+13, j+4, k+9, MEBlocks.skeletonbrick, 0, 2);
world.setBlock(i+3, j+4, k+10, MEBlocks.skeletonbrick, 0, 2);
world.setBlock(i+4, j+4, k+10, MEBlocks.skeletonbrick, 0, 2);
world.setBlock(i+5, j+4, k+10, MEBlocks.skeletonbrick, 0, 2);
world.setBlock(i+6, j+4, k+10, MEBlocks.skeletonbrick, 0, 2);
world.setBlock(i+7, j+4, k+10, MEBlocks.skeletonbrick, 0, 2);
world.setBlock(i+8, j+4, k+10, MEBlocks.skeletonbrick, 0, 2);
world.setBlock(i+9, j+4, k+10, MEBlocks.skeletonbrick, 0, 2);
world.setBlock(i+10, j+4, k+10, MEBlocks.skeletonbrick, 0, 2);
world.setBlock(i+11, j+4, k+10, MEBlocks.skeletonbrick, 0, 2);
world.setBlock(i+12, j+4, k+10, MEBlocks.skeletonbrick, 0, 2);
world.setBlock(i+13, j+4, k+10, MEBlocks.skeletonbrick, 0, 2);
world.setBlock(i+5, j+4, k+12, MEBlocks.skeletonbrick, 0, 2);
world.setBlock(i+10, j+4, k+12, MEBlocks.skeletonbrick, 0, 2);
world.setBlock(i+4, j+4, k+13, MEBlocks.skeletonbrick, 0, 2);
world.setBlock(i+5, j+4, k+13, MEBlocks.skeletonbrick, 0, 2);
world.setBlock(i+6, j+4, k+13, MEBlocks.skeletonbrick, 0, 2);
world.setBlock(i+9, j+4, k+13, MEBlocks.skeletonbrick, 0, 2);
world.setBlock(i+10, j+4, k+13, MEBlocks.skeletonbrick, 0, 2);
world.setBlock(i+11, j+4, k+13, MEBlocks.skeletonbrick, 0, 2);
world.setBlock(i+5, j+4, k+14, MEBlocks.skeletonbrick, 0, 2);
world.setBlock(i+10, j+4, k+14, MEBlocks.skeletonbrick, 0, 2);
world.setBlock(i+3, j+5, k+1, MEBlocks.skeletonbrick, 0, 2);
world.setBlock(i+4, j+5, k+1, MEBlocks.skeletonbrick, 0, 2);
world.setBlock(i+5, j+5, k+1, MEBlocks.skeletonbrick, 0, 2);
world.setBlock(i+6, j+5, k+1, MEBlocks.skeletonbrick, 0, 2);
world.setBlock(i+7, j+5, k+1, MEBlocks.skeletonbrick, 0, 2);
world.setBlock(i+8, j+5, k+1, MEBlocks.skeletonbrick, 0, 2);
world.setBlock(i+9, j+5, k+1, MEBlocks.skeletonbrick, 0, 2);
world.setBlock(i+10, j+5, k+1, MEBlocks.skeletonbrick, 0, 2);
world.setBlock(i+11, j+5, k+1, MEBlocks.skeletonbrick, 0, 2);
world.setBlock(i+12, j+5, k+1, MEBlocks.skeletonbrick, 0, 2);
world.setBlock(i+13, j+5, k+1, MEBlocks.skeletonbrick, 0, 2);
world.setBlock(i+3, j+5, k+2, MEBlocks.skeletonbrick, 0, 2);
world.setBlock(i+9, j+5, k+2, Block.getBlockById(65), 3, 2);
world.setBlock(i+13, j+5, k+2, MEBlocks.skeletonbrick, 0, 2);
world.setBlock(i+3, j+5, k+3, MEBlocks.skeletonbrick, 0, 2);
world.setBlock(i+13, j+5, k+3, MEBlocks.skeletonbrick, 0, 2);
world.setBlock(i+3, j+5, k+4, MEBlocks.skeletonbrick, 0, 2);
world.setBlock(i+13, j+5, k+4, MEBlocks.skeletonbrick, 0, 2);
world.setBlock(i+3, j+5, k+5, MEBlocks.skeletonbrick, 0, 2);
world.setBlock(i+13, j+5, k+5, MEBlocks.skeletonbrick, 0, 2);
world.setBlock(i+3, j+5, k+6, MEBlocks.skeletonbrick, 0, 2);
world.setBlock(i+13, j+5, k+6, MEBlocks.skeletonbrick, 0, 2);
world.setBlock(i+3, j+5, k+7, MEBlocks.skeletonbrick, 0, 2);
world.setBlock(i+13, j+5, k+7, MEBlocks.skeletonbrick, 0, 2);
world.setBlock(i+3, j+5, k+8, MEBlocks.skeletonbrick, 0, 2);
world.setBlock(i+13, j+5, k+8, MEBlocks.skeletonbrick, 0, 2);
world.setBlock(i+3, j+5, k+9, MEBlocks.skeletonbrick, 0, 2);
world.setBlock(i+13, j+5, k+9, MEBlocks.skeletonbrick, 0, 2);
world.setBlock(i+3, j+5, k+10, MEBlocks.skeletonbrick, 0, 2);
world.setBlock(i+4, j+5, k+10, MEBlocks.skeletonbrick, 0, 2);
world.setBlock(i+5, j+5, k+10, MEBlocks.skeletonbrick, 0, 2);
world.setBlock(i+6, j+5, k+10, MEBlocks.skeletonbrick, 0, 2);
world.setBlock(i+7, j+5, k+10, MEBlocks.skeletonbrick, 0, 2);
world.setBlock(i+8, j+5, k+10, MEBlocks.skeletonbrick, 0, 2);
world.setBlock(i+9, j+5, k+10, MEBlocks.skeletonbrick, 0, 2);
world.setBlock(i+10, j+5, k+10, MEBlocks.skeletonbrick, 0, 2);
world.setBlock(i+11, j+5, k+10, MEBlocks.skeletonbrick, 0, 2);
world.setBlock(i+12, j+5, k+10, MEBlocks.skeletonbrick, 0, 2);
world.setBlock(i+13, j+5, k+10, MEBlocks.skeletonbrick, 0, 2);
world.setBlock(i+5, j+5, k+13, MEBlocks.skeletonbrick, 0, 2);
world.setBlock(i+10, j+5, k+13, MEBlocks.skeletonbrick, 0, 2);
world.setBlock(i+3, j+6, k+1, MEBlocks.skeletonbrick, 0, 2);
world.setBlock(i+4, j+6, k+1, MEBlocks.skeletonbrick, 0, 2);
world.setBlock(i+5, j+6, k+1, MEBlocks.skeletonbrick, 0, 2);
world.setBlock(i+6, j+6, k+1, MEBlocks.skeletonbrick, 0, 2);
world.setBlock(i+7, j+6, k+1, MEBlocks.skeletonbrick, 0, 2);
world.setBlock(i+8, j+6, k+1, MEBlocks.skeletonbrick, 0, 2);
world.setBlock(i+9, j+6, k+1, MEBlocks.skeletonbrick, 0, 2);
world.setBlock(i+10, j+6, k+1, MEBlocks.skeletonbrick, 0, 2);
world.setBlock(i+11, j+6, k+1, MEBlocks.skeletonbrick, 0, 2);
world.setBlock(i+12, j+6, k+1, MEBlocks.skeletonbrick, 0, 2);
world.setBlock(i+13, j+6, k+1, MEBlocks.skeletonbrick, 0, 2);
world.setBlock(i+3, j+6, k+2, MEBlocks.skeletonbrick, 0, 2);
world.setBlock(i+4, j+6, k+2, MEBlocks.skeletonbrick, 0, 2);
world.setBlock(i+5, j+6, k+2, MEBlocks.skeletonbrick, 0, 2);
world.setBlock(i+6, j+6, k+2, MEBlocks.skeletonbrick, 0, 2);
world.setBlock(i+7, j+6, k+2, MEBlocks.skeletonbrick, 0, 2);
world.setBlock(i+8, j+6, k+2, MEBlocks.skeletonbrick, 0, 2);
world.setBlock(i+9, j+6, k+2, Block.getBlockById(65), 3, 2);
world.setBlock(i+10, j+6, k+2, MEBlocks.skeletonbrick, 0, 2);
world.setBlock(i+11, j+6, k+2, MEBlocks.skeletonbrick, 0, 2);
world.setBlock(i+12, j+6, k+2, MEBlocks.skeletonbrick, 0, 2);
world.setBlock(i+13, j+6, k+2, MEBlocks.skeletonbrick, 0, 2);
world.setBlock(i+3, j+6, k+3, MEBlocks.skeletonbrick, 0, 2);
world.setBlock(i+4, j+6, k+3, MEBlocks.skeletonbrick, 0, 2);
world.setBlock(i+5, j+6, k+3, MEBlocks.skeletonbrick, 0, 2);
world.setBlock(i+6, j+6, k+3, MEBlocks.skeletonbrick, 0, 2);
world.setBlock(i+7, j+6, k+3, MEBlocks.skeletonbrick, 0, 2);
world.setBlock(i+8, j+6, k+3, MEBlocks.skeletonbrick, 0, 2);
world.setBlock(i+9, j+6, k+3, MEBlocks.skeletonbrick, 0, 2);
world.setBlock(i+10, j+6, k+3, MEBlocks.skeletonbrick, 0, 2);
world.setBlock(i+11, j+6, k+3, MEBlocks.skeletonbrick, 0, 2);
world.setBlock(i+12, j+6, k+3, MEBlocks.skeletonbrick, 0, 2);
world.setBlock(i+13, j+6, k+3, MEBlocks.skeletonbrick, 0, 2);
world.setBlock(i+3, j+6, k+4, MEBlocks.skeletonbrick, 0, 2);
world.setBlock(i+4, j+6, k+4, MEBlocks.skeletonbrick, 0, 2);
world.setBlock(i+5, j+6, k+4, MEBlocks.skeletonbrick, 0, 2);
world.setBlock(i+6, j+6, k+4, MEBlocks.skeletonbrick, 0, 2);
world.setBlock(i+7, j+6, k+4, MEBlocks.skeletonbrick, 0, 2);
world.setBlock(i+8, j+6, k+4, MEBlocks.skeletonbrick, 0, 2);
world.setBlock(i+9, j+6, k+4, MEBlocks.skeletonbrick, 0, 2);
world.setBlock(i+10, j+6, k+4, MEBlocks.skeletonbrick, 0, 2);
world.setBlock(i+11, j+6, k+4, MEBlocks.skeletonbrick, 0, 2);
world.setBlock(i+12, j+6, k+4, MEBlocks.skeletonbrick, 0, 2);
world.setBlock(i+13, j+6, k+4, MEBlocks.skeletonbrick, 0, 2);
world.setBlock(i+3, j+6, k+5, MEBlocks.skeletonbrick, 0, 2);
world.setBlock(i+4, j+6, k+5, MEBlocks.skeletonbrick, 0, 2);
world.setBlock(i+5, j+6, k+5, MEBlocks.skeletonbrick, 0, 2);
world.setBlock(i+6, j+6, k+5, MEBlocks.skeletonbrick, 0, 2);
world.setBlock(i+7, j+6, k+5, MEBlocks.skeletonbrick, 0, 2);
world.setBlock(i+8, j+6, k+5, MEBlocks.skeletonbrick, 0, 2);
world.setBlock(i+9, j+6, k+5, MEBlocks.skeletonbrick, 0, 2);
world.setBlock(i+10, j+6, k+5, MEBlocks.skeletonbrick, 0, 2);
world.setBlock(i+11, j+6, k+5, MEBlocks.skeletonbrick, 0, 2);
world.setBlock(i+12, j+6, k+5, MEBlocks.skeletonbrick, 0, 2);
world.setBlock(i+13, j+6, k+5, MEBlocks.skeletonbrick, 0, 2);
world.setBlock(i+3, j+6, k+6, MEBlocks.skeletonbrick, 0, 2);
world.setBlock(i+4, j+6, k+6, MEBlocks.skeletonbrick, 0, 2);
world.setBlock(i+5, j+6, k+6, MEBlocks.skeletonbrick, 0, 2);
world.setBlock(i+6, j+6, k+6, MEBlocks.skeletonbrick, 0, 2);
world.setBlock(i+7, j+6, k+6, MEBlocks.skeletonbrick, 0, 2);
world.setBlock(i+8, j+6, k+6, MEBlocks.skeletonbrick, 0, 2);
world.setBlock(i+9, j+6, k+6, MEBlocks.skeletonbrick, 0, 2);
world.setBlock(i+10, j+6, k+6, MEBlocks.skeletonbrick, 0, 2);
world.setBlock(i+11, j+6, k+6, MEBlocks.skeletonbrick, 0, 2);
world.setBlock(i+12, j+6, k+6, MEBlocks.skeletonbrick, 0, 2);
world.setBlock(i+13, j+6, k+6, MEBlocks.skeletonbrick, 0, 2);
world.setBlock(i+3, j+6, k+7, MEBlocks.skeletonbrick, 0, 2);
world.setBlock(i+4, j+6, k+7, MEBlocks.skeletonbrick, 0, 2);
world.setBlock(i+5, j+6, k+7, MEBlocks.skeletonbrick, 0, 2);
world.setBlock(i+6, j+6, k+7, MEBlocks.skeletonbrick, 0, 2);
world.setBlock(i+7, j+6, k+7, MEBlocks.skeletonbrick, 0, 2);
world.setBlock(i+8, j+6, k+7, MEBlocks.skeletonbrick, 0, 2);
world.setBlock(i+9, j+6, k+7, MEBlocks.skeletonbrick, 0, 2);
world.setBlock(i+10, j+6, k+7, MEBlocks.skeletonbrick, 0, 2);
world.setBlock(i+11, j+6, k+7, MEBlocks.skeletonbrick, 0, 2);
world.setBlock(i+12, j+6, k+7, MEBlocks.skeletonbrick, 0, 2);
world.setBlock(i+13, j+6, k+7, MEBlocks.skeletonbrick, 0, 2);
world.setBlock(i+3, j+6, k+8, MEBlocks.skeletonbrick, 0, 2);
world.setBlock(i+4, j+6, k+8, MEBlocks.skeletonbrick, 0, 2);
world.setBlock(i+5, j+6, k+8, MEBlocks.skeletonbrick, 0, 2);
world.setBlock(i+6, j+6, k+8, MEBlocks.skeletonbrick, 0, 2);
world.setBlock(i+7, j+6, k+8, MEBlocks.skeletonbrick, 0, 2);
world.setBlock(i+8, j+6, k+8, MEBlocks.skeletonbrick, 0, 2);
world.setBlock(i+9, j+6, k+8, MEBlocks.skeletonbrick, 0, 2);
world.setBlock(i+10, j+6, k+8, MEBlocks.skeletonbrick, 0, 2);
world.setBlock(i+11, j+6, k+8, MEBlocks.skeletonbrick, 0, 2);
world.setBlock(i+12, j+6, k+8, MEBlocks.skeletonbrick, 0, 2);
world.setBlock(i+13, j+6, k+8, MEBlocks.skeletonbrick, 0, 2);
world.setBlock(i+3, j+6, k+9, MEBlocks.skeletonbrick, 0, 2);
world.setBlock(i+4, j+6, k+9, MEBlocks.skeletonbrick, 0, 2);
world.setBlock(i+5, j+6, k+9, MEBlocks.skeletonbrick, 0, 2);
world.setBlock(i+6, j+6, k+9, MEBlocks.skeletonbrick, 0, 2);
world.setBlock(i+7, j+6, k+9, MEBlocks.skeletonbrick, 0, 2);
world.setBlock(i+8, j+6, k+9, MEBlocks.skeletonbrick, 0, 2);
world.setBlock(i+9, j+6, k+9, MEBlocks.skeletonbrick, 0, 2);
world.setBlock(i+10, j+6, k+9, MEBlocks.skeletonbrick, 0, 2);
world.setBlock(i+11, j+6, k+9, MEBlocks.skeletonbrick, 0, 2);
world.setBlock(i+12, j+6, k+9, MEBlocks.skeletonbrick, 0, 2);
world.setBlock(i+13, j+6, k+9, MEBlocks.skeletonbrick, 0, 2);
world.setBlock(i+3, j+6, k+10, MEBlocks.skeletonbrick, 0, 2);
world.setBlock(i+4, j+6, k+10, MEBlocks.skeletonbrick, 0, 2);
world.setBlock(i+5, j+6, k+10, MEBlocks.skeletonbrick, 0, 2);
world.setBlock(i+6, j+6, k+10, MEBlocks.skeletonbrick, 0, 2);
world.setBlock(i+7, j+6, k+10, MEBlocks.skeletonbrick, 0, 2);
world.setBlock(i+8, j+6, k+10, MEBlocks.skeletonbrick, 0, 2);
world.setBlock(i+9, j+6, k+10, MEBlocks.skeletonbrick, 0, 2);
world.setBlock(i+10, j+6, k+10, MEBlocks.skeletonbrick, 0, 2);
world.setBlock(i+11, j+6, k+10, MEBlocks.skeletonbrick, 0, 2);
world.setBlock(i+12, j+6, k+10, MEBlocks.skeletonbrick, 0, 2);
world.setBlock(i+13, j+6, k+10, MEBlocks.skeletonbrick, 0, 2);
world.setBlock(i+3, j+7, k+1, MEBlocks.skeletonbrick, 0, 2);
world.setBlock(i+4, j+7, k+1, MEBlocks.skeletonbrick, 0, 2);
world.setBlock(i+5, j+7, k+1, MEBlocks.skeletonbrick, 0, 2);
world.setBlock(i+6, j+7, k+1, MEBlocks.skeletonbrick, 0, 2);
world.setBlock(i+7, j+7, k+1, MEBlocks.skeletonbrick, 0, 2);
world.setBlock(i+8, j+7, k+1, MEBlocks.skeletonbrick, 0, 2);
world.setBlock(i+9, j+7, k+1, MEBlocks.skeletonbrick, 0, 2);
world.setBlock(i+10, j+7, k+1, MEBlocks.skeletonbrick, 0, 2);
world.setBlock(i+11, j+7, k+1, MEBlocks.skeletonbrick, 0, 2);
world.setBlock(i+12, j+7, k+1, MEBlocks.skeletonbrick, 0, 2);
world.setBlock(i+13, j+7, k+1, MEBlocks.skeletonbrick, 0, 2);
world.setBlock(i+3, j+7, k+2, MEBlocks.skeletonbrick, 0, 2);
world.setBlock(i+4, j+7, k+2, Block.getBlockById(11), 0, 2);
world.setBlock(i+5, j+7, k+2, MEBlocks.skeletonbrick, 0, 2);
world.setBlock(i+6, j+7, k+2, MEBlocks.skeletonbrick, 0, 2);
world.setBlock(i+7, j+7, k+2, MEBlocks.skeletonbrick, 0, 2);
world.setBlock(i+8, j+7, k+2, MEBlocks.skeletonbrick, 0, 2);
world.setBlock(i+9, j+7, k+2, Block.getBlockById(65), 3, 2);
world.setBlock(i+10, j+7, k+2, MEBlocks.skeletonbrick, 0, 2);
world.setBlock(i+11, j+7, k+2, MEBlocks.skeletonbrick, 0, 2);
world.setBlock(i+12, j+7, k+2, Block.getBlockById(11), 0, 2);
world.setBlock(i+13, j+7, k+2, MEBlocks.skeletonbrick, 0, 2);
world.setBlock(i+3, j+7, k+3, MEBlocks.skeletonbrick, 0, 2);
world.setBlock(i+4, j+7, k+3, MEBlocks.skeletonbrick, 0, 2);
world.setBlock(i+5, j+7, k+3, MEBlocks.skeletonbrick, 0, 2);
world.setBlock(i+6, j+7, k+3, MEBlocks.skeletonbrick, 0, 2);
world.setBlock(i+7, j+7, k+3, MEBlocks.skeletonbrick, 0, 2);
world.setBlock(i+8, j+7, k+3, MEBlocks.skeletonbrick, 0, 2);
world.setBlock(i+9, j+7, k+3, MEBlocks.skeletonbrick, 0, 2);
world.setBlock(i+10, j+7, k+3, MEBlocks.skeletonbrick, 0, 2);
world.setBlock(i+11, j+7, k+3, MEBlocks.skeletonbrick, 0, 2);
world.setBlock(i+12, j+7, k+3, MEBlocks.skeletonbrick, 0, 2);
world.setBlock(i+13, j+7, k+3, MEBlocks.skeletonbrick, 0, 2);
world.setBlock(i+3, j+7, k+4, MEBlocks.skeletonbrick, 0, 2);
world.setBlock(i+4, j+7, k+4, MEBlocks.skeletonbrick, 0, 2);
world.setBlock(i+5, j+7, k+4, MEBlocks.skeletonbrick, 0, 2);
world.setBlock(i+6, j+7, k+4, MEBlocks.skeletonbrick, 0, 2);
world.setBlock(i+7, j+7, k+4, MEBlocks.skeletonbrick, 0, 2);
world.setBlock(i+8, j+7, k+4, MEBlocks.skeletonbrick, 0, 2);
world.setBlock(i+9, j+7, k+4, MEBlocks.skeletonbrick, 0, 2);
world.setBlock(i+10, j+7, k+4, MEBlocks.skeletonbrick, 0, 2);
world.setBlock(i+11, j+7, k+4, MEBlocks.skeletonbrick, 0, 2);
world.setBlock(i+12, j+7, k+4, MEBlocks.skeletonbrick, 0, 2);
world.setBlock(i+13, j+7, k+4, MEBlocks.skeletonbrick, 0, 2);
world.setBlock(i+3, j+7, k+5, MEBlocks.skeletonbrick, 0, 2);
world.setBlock(i+4, j+7, k+5, MEBlocks.skeletonbrick, 0, 2);
world.setBlock(i+5, j+7, k+5, MEBlocks.skeletonbrick, 0, 2);
world.setBlock(i+6, j+7, k+5, MEBlocks.skeletonbrick, 0, 2);
world.setBlock(i+7, j+7, k+5, MEBlocks.skeletonbrick, 0, 2);
world.setBlock(i+8, j+7, k+5, MEBlocks.skeletonbrick, 0, 2);
world.setBlock(i+9, j+7, k+5, MEBlocks.skeletonbrick, 0, 2);
world.setBlock(i+10, j+7, k+5, MEBlocks.skeletonbrick, 0, 2);
world.setBlock(i+11, j+7, k+5, MEBlocks.skeletonbrick, 0, 2);
world.setBlock(i+12, j+7, k+5, MEBlocks.skeletonbrick, 0, 2);
world.setBlock(i+13, j+7, k+5, MEBlocks.skeletonbrick, 0, 2);
world.setBlock(i+3, j+7, k+6, MEBlocks.skeletonbrick, 0, 2);
world.setBlock(i+4, j+7, k+6, MEBlocks.skeletonbrick, 0, 2);
world.setBlock(i+5, j+7, k+6, MEBlocks.skeletonbrick, 0, 2);
world.setBlock(i+6, j+7, k+6, MEBlocks.skeletonbrick, 0, 2);
world.setBlock(i+7, j+7, k+6, MEBlocks.skeletonbrick, 0, 2);
world.setBlock(i+8, j+7, k+6, MEBlocks.skeletonbrick, 0, 2);
world.setBlock(i+9, j+7, k+6, MEBlocks.skeletonbrick, 0, 2);
world.setBlock(i+10, j+7, k+6, MEBlocks.skeletonbrick, 0, 2);
world.setBlock(i+11, j+7, k+6, MEBlocks.skeletonbrick, 0, 2);
world.setBlock(i+12, j+7, k+6, MEBlocks.skeletonbrick, 0, 2);
world.setBlock(i+13, j+7, k+6, MEBlocks.skeletonbrick, 0, 2);
world.setBlock(i+3, j+7, k+7, MEBlocks.skeletonbrick, 0, 2);
world.setBlock(i+4, j+7, k+7, MEBlocks.skeletonbrick, 0, 2);
world.setBlock(i+5, j+7, k+7, MEBlocks.skeletonbrick, 0, 2);
world.setBlock(i+6, j+7, k+7, MEBlocks.skeletonbrick, 0, 2);
world.setBlock(i+7, j+7, k+7, MEBlocks.skeletonbrick, 0, 2);
world.setBlock(i+8, j+7, k+7, MEBlocks.skeletonbrick, 0, 2);
world.setBlock(i+9, j+7, k+7, MEBlocks.skeletonbrick, 0, 2);
world.setBlock(i+10, j+7, k+7, MEBlocks.skeletonbrick, 0, 2);
world.setBlock(i+11, j+7, k+7, MEBlocks.skeletonbrick, 0, 2);
world.setBlock(i+12, j+7, k+7, MEBlocks.skeletonbrick, 0, 2);
world.setBlock(i+13, j+7, k+7, MEBlocks.skeletonbrick, 0, 2);
world.setBlock(i+3, j+7, k+8, MEBlocks.skeletonbrick, 0, 2);
world.setBlock(i+4, j+7, k+8, MEBlocks.skeletonbrick, 0, 2);
world.setBlock(i+5, j+7, k+8, MEBlocks.skeletonbrick, 0, 2);
world.setBlock(i+6, j+7, k+8, MEBlocks.skeletonbrick, 0, 2);
world.setBlock(i+7, j+7, k+8, MEBlocks.skeletonbrick, 0, 2);
world.setBlock(i+8, j+7, k+8, MEBlocks.skeletonbrick, 0, 2);
world.setBlock(i+9, j+7, k+8, MEBlocks.skeletonbrick, 0, 2);
world.setBlock(i+10, j+7, k+8, MEBlocks.skeletonbrick, 0, 2);
world.setBlock(i+11, j+7, k+8, MEBlocks.skeletonbrick, 0, 2);
world.setBlock(i+12, j+7, k+8, MEBlocks.skeletonbrick, 0, 2);
world.setBlock(i+13, j+7, k+8, MEBlocks.skeletonbrick, 0, 2);
world.setBlock(i+3, j+7, k+9, MEBlocks.skeletonbrick, 0, 2);
world.setBlock(i+4, j+7, k+9, Block.getBlockById(11), 0, 2);
world.setBlock(i+5, j+7, k+9, MEBlocks.skeletonbrick, 0, 2);
world.setBlock(i+6, j+7, k+9, MEBlocks.skeletonbrick, 0, 2);
world.setBlock(i+7, j+7, k+9, MEBlocks.skeletonbrick, 0, 2);
world.setBlock(i+8, j+7, k+9, MEBlocks.skeletonbrick, 0, 2);
world.setBlock(i+9, j+7, k+9, MEBlocks.skeletonbrick, 0, 2);
world.setBlock(i+10, j+7, k+9, MEBlocks.skeletonbrick, 0, 2);
world.setBlock(i+11, j+7, k+9, MEBlocks.skeletonbrick, 0, 2);
world.setBlock(i+12, j+7, k+9, Block.getBlockById(11), 0, 2);
world.setBlock(i+13, j+7, k+9, MEBlocks.skeletonbrick, 0, 2);
world.setBlock(i+3, j+7, k+10, MEBlocks.skeletonbrick, 0, 2);
world.setBlock(i+4, j+7, k+10, MEBlocks.skeletonbrick, 0, 2);
world.setBlock(i+5, j+7, k+10, MEBlocks.skeletonbrick, 0, 2);
world.setBlock(i+6, j+7, k+10, MEBlocks.skeletonbrick, 0, 2);
world.setBlock(i+7, j+7, k+10, MEBlocks.skeletonbrick, 0, 2);
world.setBlock(i+8, j+7, k+10, MEBlocks.skeletonbrick, 0, 2);
world.setBlock(i+9, j+7, k+10, MEBlocks.skeletonbrick, 0, 2);
world.setBlock(i+10, j+7, k+10, MEBlocks.skeletonbrick, 0, 2);
world.setBlock(i+11, j+7, k+10, MEBlocks.skeletonbrick, 0, 2);
world.setBlock(i+12, j+7, k+10, MEBlocks.skeletonbrick, 0, 2);
world.setBlock(i+13, j+7, k+10, MEBlocks.skeletonbrick, 0, 2);
world.setBlock(i+3, j+8, k+1, MEBlocks.skeletonbrick, 0, 2);
world.setBlock(i+4, j+8, k+1, MEBlocks.skeletonbrick, 0, 2);
world.setBlock(i+5, j+8, k+1, MEBlocks.skeletonbrick, 0, 2);
world.setBlock(i+6, j+8, k+1, MEBlocks.skeletonbrick, 0, 2);
world.setBlock(i+7, j+8, k+1, MEBlocks.skeletonbrick, 0, 2);
world.setBlock(i+8, j+8, k+1, MEBlocks.skeletonbrick, 0, 2);
world.setBlock(i+9, j+8, k+1, MEBlocks.skeletonbrick, 0, 2);
world.setBlock(i+10, j+8, k+1, MEBlocks.skeletonbrick, 0, 2);
world.setBlock(i+11, j+8, k+1, MEBlocks.skeletonbrick, 0, 2);
world.setBlock(i+12, j+8, k+1, MEBlocks.skeletonbrick, 0, 2);
world.setBlock(i+13, j+8, k+1, MEBlocks.skeletonbrick, 0, 2);
world.setBlock(i+3, j+8, k+2, MEBlocks.skeletonbrick, 0, 2);
world.setBlock(i+5, j+8, k+2, MEBlocks.skeletonbrick, 0, 2);
world.setBlock(i+7, j+8, k+2, Block.getBlockById(25), 0, 2);
world.setBlock(i+8, j+8, k+2, Block.getBlockById(25), 0, 2);
world.setBlock(i+11, j+8, k+2, MEBlocks.skeletonbrick, 0, 2);
world.setBlock(i+13, j+8, k+2, MEBlocks.skeletonbrick, 0, 2);
world.setBlock(i+3, j+8, k+3, MEBlocks.skeletonbrick, 0, 2);
world.setBlock(i+4, j+8, k+3, MEBlocks.skeletonbrick, 0, 2);
world.setBlock(i+12, j+8, k+3, MEBlocks.skeletonbrick, 0, 2);
world.setBlock(i+13, j+8, k+3, MEBlocks.skeletonbrick, 0, 2);
world.setBlock(i+3, j+8, k+4, MEBlocks.skeletonbrick, 0, 2);
world.setBlock(i+13, j+8, k+4, MEBlocks.skeletonbrick, 0, 2);
world.setBlock(i+3, j+8, k+5, MEBlocks.skeletonbrick, 0, 2);
world.setBlock(i+4, j+8, k+5, Block.getBlockById(25), 0, 2);
world.setBlock(i+12, j+8, k+5, Block.getBlockById(25), 0, 2);
world.setBlock(i+13, j+8, k+5, MEBlocks.skeletonbrick, 0, 2);
world.setBlock(i+3, j+8, k+6, MEBlocks.skeletonbrick, 0, 2);
world.setBlock(i+4, j+8, k+6, Block.getBlockById(25), 0, 2);
world.setBlock(i+12, j+8, k+6, Block.getBlockById(25), 0, 2);
world.setBlock(i+13, j+8, k+6, MEBlocks.skeletonbrick, 0, 2);
world.setBlock(i+3, j+8, k+7, MEBlocks.skeletonbrick, 0, 2);
world.setBlock(i+13, j+8, k+7, MEBlocks.skeletonbrick, 0, 2);
world.setBlock(i+3, j+8, k+8, MEBlocks.skeletonbrick, 0, 2);
world.setBlock(i+4, j+8, k+8, MEBlocks.skeletonbrick, 0, 2);
world.setBlock(i+12, j+8, k+8, MEBlocks.skeletonbrick, 0, 2);
world.setBlock(i+13, j+8, k+8, MEBlocks.skeletonbrick, 0, 2);
world.setBlock(i+3, j+8, k+9, MEBlocks.skeletonbrick, 0, 2);
world.setBlock(i+5, j+8, k+9, MEBlocks.skeletonbrick, 0, 2);
world.setBlock(i+7, j+8, k+9, Block.getBlockById(25), 0, 2);
world.setBlock(i+8, j+8, k+9, Block.getBlockById(25), 0, 2);
world.setBlock(i+9, j+8, k+9, Block.getBlockById(65), 2, 2);
world.setBlock(i+11, j+8, k+9, MEBlocks.skeletonbrick, 0, 2);
world.setBlock(i+13, j+8, k+9, MEBlocks.skeletonbrick, 0, 2);
world.setBlock(i+3, j+8, k+10, MEBlocks.skeletonbrick, 0, 2);
world.setBlock(i+4, j+8, k+10, MEBlocks.skeletonbrick, 0, 2);
world.setBlock(i+5, j+8, k+10, MEBlocks.skeletonbrick, 0, 2);
world.setBlock(i+6, j+8, k+10, MEBlocks.skeletonbrick, 0, 2);
world.setBlock(i+7, j+8, k+10, MEBlocks.skeletonbrick, 0, 2);
world.setBlock(i+8, j+8, k+10, MEBlocks.skeletonbrick, 0, 2);
world.setBlock(i+9, j+8, k+10, MEBlocks.skeletonbrick, 0, 2);
world.setBlock(i+10, j+8, k+10, MEBlocks.skeletonbrick, 0, 2);
world.setBlock(i+11, j+8, k+10, MEBlocks.skeletonbrick, 0, 2);
world.setBlock(i+12, j+8, k+10, MEBlocks.skeletonbrick, 0, 2);
world.setBlock(i+13, j+8, k+10, MEBlocks.skeletonbrick, 0, 2);
world.setBlock(i+3, j+9, k+1, MEBlocks.skeletonbrick, 0, 2);
world.setBlock(i+4, j+9, k+1, MEBlocks.skeletonbrick, 0, 2);
world.setBlock(i+5, j+9, k+1, MEBlocks.skeletonbrick, 0, 2);
world.setBlock(i+6, j+9, k+1, MEBlocks.skeletonbrick, 0, 2);
world.setBlock(i+7, j+9, k+1, MEBlocks.skeletonbrick, 0, 2);
world.setBlock(i+8, j+9, k+1, MEBlocks.skeletonbrick, 0, 2);
world.setBlock(i+9, j+9, k+1, MEBlocks.skeletonbrick, 0, 2);
world.setBlock(i+10, j+9, k+1, MEBlocks.skeletonbrick, 0, 2);
world.setBlock(i+11, j+9, k+1, MEBlocks.skeletonbrick, 0, 2);
world.setBlock(i+12, j+9, k+1, MEBlocks.skeletonbrick, 0, 2);
world.setBlock(i+13, j+9, k+1, MEBlocks.skeletonbrick, 0, 2);
world.setBlock(i+3, j+9, k+2, MEBlocks.skeletonbrick, 0, 2);
world.setBlock(i+5, j+9, k+2, MEBlocks.skeletonbrick, 0, 2);
world.setBlock(i+11, j+9, k+2, MEBlocks.skeletonbrick, 0, 2);
world.setBlock(i+13, j+9, k+2, MEBlocks.skeletonbrick, 0, 2);
world.setBlock(i+3, j+9, k+3, MEBlocks.skeletonbrick, 0, 2);
world.setBlock(i+4, j+9, k+3, MEBlocks.skeletonbrick, 0, 2);
world.setBlock(i+12, j+9, k+3, MEBlocks.skeletonbrick, 0, 2);
world.setBlock(i+13, j+9, k+3, MEBlocks.skeletonbrick, 0, 2);
world.setBlock(i+3, j+9, k+4, MEBlocks.skeletonbrick, 0, 2);
world.setBlock(i+13, j+9, k+4, MEBlocks.skeletonbrick, 0, 2);
world.setBlock(i+3, j+9, k+5, MEBlocks.skeletonbrick, 0, 2);
world.setBlock(i+13, j+9, k+5, MEBlocks.skeletonbrick, 0, 2);
world.setBlock(i+3, j+9, k+6, MEBlocks.skeletonbrick, 0, 2);
world.setBlock(i+13, j+9, k+6, MEBlocks.skeletonbrick, 0, 2);
world.setBlock(i+3, j+9, k+7, MEBlocks.skeletonbrick, 0, 2);
world.setBlock(i+13, j+9, k+7, MEBlocks.skeletonbrick, 0, 2);
world.setBlock(i+3, j+9, k+8, MEBlocks.skeletonbrick, 0, 2);
world.setBlock(i+4, j+9, k+8, MEBlocks.skeletonbrick, 0, 2);
world.setBlock(i+12, j+9, k+8, MEBlocks.skeletonbrick, 0, 2);
world.setBlock(i+13, j+9, k+8, MEBlocks.skeletonbrick, 0, 2);
world.setBlock(i+3, j+9, k+9, MEBlocks.skeletonbrick, 0, 2);
world.setBlock(i+5, j+9, k+9, MEBlocks.skeletonbrick, 0, 2);
world.setBlock(i+9, j+9, k+9, Block.getBlockById(65), 2, 2);
world.setBlock(i+11, j+9, k+9, MEBlocks.skeletonbrick, 0, 2);
world.setBlock(i+13, j+9, k+9, MEBlocks.skeletonbrick, 0, 2);
world.setBlock(i+3, j+9, k+10, MEBlocks.skeletonbrick, 0, 2);
world.setBlock(i+4, j+9, k+10, MEBlocks.skeletonbrick, 0, 2);
world.setBlock(i+5, j+9, k+10, MEBlocks.skeletonbrick, 0, 2);
world.setBlock(i+6, j+9, k+10, MEBlocks.skeletonbrick, 0, 2);
world.setBlock(i+7, j+9, k+10, MEBlocks.skeletonbrick, 0, 2);
world.setBlock(i+8, j+9, k+10, MEBlocks.skeletonbrick, 0, 2);
world.setBlock(i+9, j+9, k+10, MEBlocks.skeletonbrick, 0, 2);
world.setBlock(i+10, j+9, k+10, MEBlocks.skeletonbrick, 0, 2);
world.setBlock(i+11, j+9, k+10, MEBlocks.skeletonbrick, 0, 2);
world.setBlock(i+12, j+9, k+10, MEBlocks.skeletonbrick, 0, 2);
world.setBlock(i+13, j+9, k+10, MEBlocks.skeletonbrick, 0, 2);
world.setBlock(i+3, j+10, k+1, MEBlocks.skeletonbrick, 0, 2);
world.setBlock(i+4, j+10, k+1, MEBlocks.skeletonbrick, 0, 2);
world.setBlock(i+5, j+10, k+1, MEBlocks.skeletonbrick, 0, 2);
world.setBlock(i+6, j+10, k+1, MEBlocks.skeletonbrick, 0, 2);
world.setBlock(i+7, j+10, k+1, MEBlocks.skeletonbrick, 0, 2);
world.setBlock(i+8, j+10, k+1, MEBlocks.skeletonbrick, 0, 2);
world.setBlock(i+9, j+10, k+1, MEBlocks.skeletonbrick, 0, 2);
world.setBlock(i+10, j+10, k+1, MEBlocks.skeletonbrick, 0, 2);
world.setBlock(i+11, j+10, k+1, MEBlocks.skeletonbrick, 0, 2);
world.setBlock(i+12, j+10, k+1, MEBlocks.skeletonbrick, 0, 2);
world.setBlock(i+13, j+10, k+1, MEBlocks.skeletonbrick, 0, 2);
world.setBlock(i+3, j+10, k+2, MEBlocks.skeletonbrick, 0, 2);
world.setBlock(i+5, j+10, k+2, MEBlocks.skeletonbrick, 0, 2);
world.setBlock(i+11, j+10, k+2, MEBlocks.skeletonbrick, 0, 2);
world.setBlock(i+13, j+10, k+2, MEBlocks.skeletonbrick, 0, 2);
world.setBlock(i+3, j+10, k+3, MEBlocks.skeletonbrick, 0, 2);
world.setBlock(i+4, j+10, k+3, MEBlocks.skeletonbrick, 0, 2);
world.setBlock(i+12, j+10, k+3, MEBlocks.skeletonbrick, 0, 2);
world.setBlock(i+13, j+10, k+3, MEBlocks.skeletonbrick, 0, 2);
world.setBlock(i+3, j+10, k+4, MEBlocks.skeletonbrick, 0, 2);
world.setBlock(i+13, j+10, k+4, MEBlocks.skeletonbrick, 0, 2);
world.setBlock(i+3, j+10, k+5, MEBlocks.skeletonbrick, 0, 2);
world.setBlock(i+13, j+10, k+5, MEBlocks.skeletonbrick, 0, 2);
world.setBlock(i+3, j+10, k+6, MEBlocks.skeletonbrick, 0, 2);
world.setBlock(i+13, j+10, k+6, MEBlocks.skeletonbrick, 0, 2);
world.setBlock(i+3, j+10, k+7, MEBlocks.skeletonbrick, 0, 2);
world.setBlock(i+13, j+10, k+7, MEBlocks.skeletonbrick, 0, 2);
world.setBlock(i+3, j+10, k+8, MEBlocks.skeletonbrick, 0, 2);
world.setBlock(i+4, j+10, k+8, MEBlocks.skeletonbrick, 0, 2);
world.setBlock(i+12, j+10, k+8, MEBlocks.skeletonbrick, 0, 2);
world.setBlock(i+13, j+10, k+8, MEBlocks.skeletonbrick, 0, 2);
world.setBlock(i+3, j+10, k+9, MEBlocks.skeletonbrick, 0, 2);
world.setBlock(i+5, j+10, k+9, MEBlocks.skeletonbrick, 0, 2);
world.setBlock(i+9, j+10, k+9, Block.getBlockById(65), 2, 2);
world.setBlock(i+11, j+10, k+9, MEBlocks.skeletonbrick, 0, 2);
world.setBlock(i+13, j+10, k+9, MEBlocks.skeletonbrick, 0, 2);
world.setBlock(i+3, j+10, k+10, MEBlocks.skeletonbrick, 0, 2);
world.setBlock(i+4, j+10, k+10, MEBlocks.skeletonbrick, 0, 2);
world.setBlock(i+5, j+10, k+10, MEBlocks.skeletonbrick, 0, 2);
world.setBlock(i+6, j+10, k+10, MEBlocks.skeletonbrick, 0, 2);
world.setBlock(i+7, j+10, k+10, MEBlocks.skeletonbrick, 0, 2);
world.setBlock(i+8, j+10, k+10, MEBlocks.skeletonbrick, 0, 2);
world.setBlock(i+9, j+10, k+10, MEBlocks.skeletonbrick, 0, 2);
world.setBlock(i+10, j+10, k+10, MEBlocks.skeletonbrick, 0, 2);
world.setBlock(i+11, j+10, k+10, MEBlocks.skeletonbrick, 0, 2);
world.setBlock(i+12, j+10, k+10, MEBlocks.skeletonbrick, 0, 2);
world.setBlock(i+13, j+10, k+10, MEBlocks.skeletonbrick, 0, 2);
world.setBlock(i+3, j+11, k+1, MEBlocks.skeletonbrick, 0, 2);
world.setBlock(i+4, j+11, k+1, MEBlocks.skeletonbrick, 0, 2);
world.setBlock(i+5, j+11, k+1, MEBlocks.skeletonbrick, 0, 2);
world.setBlock(i+6, j+11, k+1, MEBlocks.skeletonbrick, 0, 2);
world.setBlock(i+7, j+11, k+1, MEBlocks.skeletonbrick, 0, 2);
world.setBlock(i+8, j+11, k+1, MEBlocks.skeletonbrick, 0, 2);
world.setBlock(i+9, j+11, k+1, MEBlocks.skeletonbrick, 0, 2);
world.setBlock(i+10, j+11, k+1, MEBlocks.skeletonbrick, 0, 2);
world.setBlock(i+11, j+11, k+1, MEBlocks.skeletonbrick, 0, 2);
world.setBlock(i+12, j+11, k+1, MEBlocks.skeletonbrick, 0, 2);
world.setBlock(i+13, j+11, k+1, MEBlocks.skeletonbrick, 0, 2);
world.setBlock(i+3, j+11, k+2, MEBlocks.skeletonbrick, 0, 2);
world.setBlock(i+13, j+11, k+2, MEBlocks.skeletonbrick, 0, 2);
world.setBlock(i+3, j+11, k+3, MEBlocks.skeletonbrick, 0, 2);
world.setBlock(i+13, j+11, k+3, MEBlocks.skeletonbrick, 0, 2);
world.setBlock(i+3, j+11, k+4, MEBlocks.skeletonbrick, 0, 2);
world.setBlock(i+13, j+11, k+4, MEBlocks.skeletonbrick, 0, 2);
world.setBlock(i+3, j+11, k+5, MEBlocks.skeletonbrick, 0, 2);
world.setBlock(i+13, j+11, k+5, MEBlocks.skeletonbrick, 0, 2);
world.setBlock(i+3, j+11, k+6, MEBlocks.skeletonbrick, 0, 2);
world.setBlock(i+13, j+11, k+6, MEBlocks.skeletonbrick, 0, 2);
world.setBlock(i+3, j+11, k+7, MEBlocks.skeletonbrick, 0, 2);
world.setBlock(i+13, j+11, k+7, MEBlocks.skeletonbrick, 0, 2);
world.setBlock(i+3, j+11, k+8, MEBlocks.skeletonbrick, 0, 2);
world.setBlock(i+13, j+11, k+8, MEBlocks.skeletonbrick, 0, 2);
world.setBlock(i+3, j+11, k+9, MEBlocks.skeletonbrick, 0, 2);
world.setBlock(i+9, j+11, k+9, Block.getBlockById(65), 2, 2);
world.setBlock(i+13, j+11, k+9, MEBlocks.skeletonbrick, 0, 2);
world.setBlock(i+3, j+11, k+10, MEBlocks.skeletonbrick, 0, 2);
world.setBlock(i+4, j+11, k+10, MEBlocks.skeletonbrick, 0, 2);
world.setBlock(i+5, j+11, k+10, MEBlocks.skeletonbrick, 0, 2);
world.setBlock(i+6, j+11, k+10, MEBlocks.skeletonbrick, 0, 2);
world.setBlock(i+7, j+11, k+10, MEBlocks.skeletonbrick, 0, 2);
world.setBlock(i+8, j+11, k+10, MEBlocks.skeletonbrick, 0, 2);
world.setBlock(i+9, j+11, k+10, MEBlocks.skeletonbrick, 0, 2);
world.setBlock(i+10, j+11, k+10, MEBlocks.skeletonbrick, 0, 2);
world.setBlock(i+11, j+11, k+10, MEBlocks.skeletonbrick, 0, 2);
world.setBlock(i+12, j+11, k+10, MEBlocks.skeletonbrick, 0, 2);
world.setBlock(i+13, j+11, k+10, MEBlocks.skeletonbrick, 0, 2);
world.setBlock(i+3, j+12, k+1, MEBlocks.skeletonbrick, 0, 2);
world.setBlock(i+4, j+12, k+1, MEBlocks.skeletonbrick, 0, 2);
world.setBlock(i+5, j+12, k+1, MEBlocks.skeletonbrick, 0, 2);
world.setBlock(i+6, j+12, k+1, MEBlocks.skeletonbrick, 0, 2);
world.setBlock(i+7, j+12, k+1, MEBlocks.skeletonbrick, 0, 2);
world.setBlock(i+8, j+12, k+1, MEBlocks.skeletonbrick, 0, 2);
world.setBlock(i+9, j+12, k+1, MEBlocks.skeletonbrick, 0, 2);
world.setBlock(i+10, j+12, k+1, MEBlocks.skeletonbrick, 0, 2);
world.setBlock(i+11, j+12, k+1, MEBlocks.skeletonbrick, 0, 2);
world.setBlock(i+12, j+12, k+1, MEBlocks.skeletonbrick, 0, 2);
world.setBlock(i+13, j+12, k+1, MEBlocks.skeletonbrick, 0, 2);
world.setBlock(i+3, j+12, k+2, MEBlocks.skeletonbrick, 0, 2);
world.setBlock(i+13, j+12, k+2, MEBlocks.skeletonbrick, 0, 2);
world.setBlock(i+3, j+12, k+3, MEBlocks.skeletonbrick, 0, 2);
world.setBlock(i+13, j+12, k+3, MEBlocks.skeletonbrick, 0, 2);
world.setBlock(i+3, j+12, k+4, MEBlocks.skeletonbrick, 0, 2);
world.setBlock(i+13, j+12, k+4, MEBlocks.skeletonbrick, 0, 2);
world.setBlock(i+3, j+12, k+5, MEBlocks.skeletonbrick, 0, 2);
world.setBlock(i+13, j+12, k+5, MEBlocks.skeletonbrick, 0, 2);
world.setBlock(i+3, j+12, k+6, MEBlocks.skeletonbrick, 0, 2);
world.setBlock(i+13, j+12, k+6, MEBlocks.skeletonbrick, 0, 2);
world.setBlock(i+3, j+12, k+7, MEBlocks.skeletonbrick, 0, 2);
world.setBlock(i+13, j+12, k+7, MEBlocks.skeletonbrick, 0, 2);
world.setBlock(i+3, j+12, k+8, MEBlocks.skeletonbrick, 0, 2);
world.setBlock(i+13, j+12, k+8, MEBlocks.skeletonbrick, 0, 2);
world.setBlock(i+3, j+12, k+9, MEBlocks.skeletonbrick, 0, 2);
world.setBlock(i+9, j+12, k+9, Block.getBlockById(65), 2, 2);
world.setBlock(i+13, j+12, k+9, MEBlocks.skeletonbrick, 0, 2);
world.setBlock(i+3, j+12, k+10, MEBlocks.skeletonbrick, 0, 2);
world.setBlock(i+4, j+12, k+10, MEBlocks.skeletonbrick, 0, 2);
world.setBlock(i+5, j+12, k+10, MEBlocks.skeletonbrick, 0, 2);
world.setBlock(i+6, j+12, k+10, MEBlocks.skeletonbrick, 0, 2);
world.setBlock(i+7, j+12, k+10, MEBlocks.skeletonbrick, 0, 2);
world.setBlock(i+8, j+12, k+10, MEBlocks.skeletonbrick, 0, 2);
world.setBlock(i+9, j+12, k+10, MEBlocks.skeletonbrick, 0, 2);
world.setBlock(i+10, j+12, k+10, MEBlocks.skeletonbrick, 0, 2);
world.setBlock(i+11, j+12, k+10, MEBlocks.skeletonbrick, 0, 2);
world.setBlock(i+12, j+12, k+10, MEBlocks.skeletonbrick, 0, 2);
world.setBlock(i+13, j+12, k+10, MEBlocks.skeletonbrick, 0, 2);
world.setBlock(i+3, j+13, k+1, MEBlocks.skeletonbrick, 0, 2);
world.setBlock(i+4, j+13, k+1, MEBlocks.skeletonbrick, 0, 2);
world.setBlock(i+5, j+13, k+1, MEBlocks.skeletonbrick, 0, 2);
world.setBlock(i+6, j+13, k+1, MEBlocks.skeletonbrick, 0, 2);
world.setBlock(i+7, j+13, k+1, MEBlocks.skeletonbrick, 0, 2);
world.setBlock(i+8, j+13, k+1, MEBlocks.skeletonbrick, 0, 2);
world.setBlock(i+9, j+13, k+1, MEBlocks.skeletonbrick, 0, 2);
world.setBlock(i+10, j+13, k+1, MEBlocks.skeletonbrick, 0, 2);
world.setBlock(i+11, j+13, k+1, MEBlocks.skeletonbrick, 0, 2);
world.setBlock(i+12, j+13, k+1, MEBlocks.skeletonbrick, 0, 2);
world.setBlock(i+13, j+13, k+1, MEBlocks.skeletonbrick, 0, 2);
world.setBlock(i+3, j+13, k+2, MEBlocks.skeletonbrick, 0, 2);
world.setBlock(i+4, j+13, k+2, MEBlocks.skeletonbrick, 0, 2);
world.setBlock(i+5, j+13, k+2, MEBlocks.skeletonbrick, 0, 2);
world.setBlock(i+6, j+13, k+2, MEBlocks.skeletonbrick, 0, 2);
world.setBlock(i+7, j+13, k+2, MEBlocks.skeletonbrick, 0, 2);
world.setBlock(i+8, j+13, k+2, MEBlocks.skeletonbrick, 0, 2);
world.setBlock(i+9, j+13, k+2, MEBlocks.skeletonbrick, 0, 2);
world.setBlock(i+10, j+13, k+2, MEBlocks.skeletonbrick, 0, 2);
world.setBlock(i+11, j+13, k+2, MEBlocks.skeletonbrick, 0, 2);
world.setBlock(i+12, j+13, k+2, MEBlocks.skeletonbrick, 0, 2);
world.setBlock(i+13, j+13, k+2, MEBlocks.skeletonbrick, 0, 2);
world.setBlock(i+3, j+13, k+3, MEBlocks.skeletonbrick, 0, 2);
world.setBlock(i+4, j+13, k+3, MEBlocks.skeletonbrick, 0, 2);
world.setBlock(i+5, j+13, k+3, MEBlocks.skeletonbrick, 0, 2);
world.setBlock(i+6, j+13, k+3, MEBlocks.skeletonbrick, 0, 2);
world.setBlock(i+7, j+13, k+3, MEBlocks.skeletonbrick, 0, 2);
world.setBlock(i+8, j+13, k+3, MEBlocks.skeletonbrick, 0, 2);
world.setBlock(i+9, j+13, k+3, MEBlocks.skeletonbrick, 0, 2);
world.setBlock(i+10, j+13, k+3, MEBlocks.skeletonbrick, 0, 2);
world.setBlock(i+11, j+13, k+3, MEBlocks.skeletonbrick, 0, 2);
world.setBlock(i+12, j+13, k+3, MEBlocks.skeletonbrick, 0, 2);
world.setBlock(i+13, j+13, k+3, MEBlocks.skeletonbrick, 0, 2);
world.setBlock(i+3, j+13, k+4, MEBlocks.skeletonbrick, 0, 2);
world.setBlock(i+4, j+13, k+4, MEBlocks.skeletonbrick, 0, 2);
world.setBlock(i+5, j+13, k+4, MEBlocks.skeletonbrick, 0, 2);
world.setBlock(i+6, j+13, k+4, MEBlocks.skeletonbrick, 0, 2);
world.setBlock(i+7, j+13, k+4, MEBlocks.skeletonbrick, 0, 2);
world.setBlock(i+8, j+13, k+4, MEBlocks.skeletonbrick, 0, 2);
world.setBlock(i+9, j+13, k+4, MEBlocks.skeletonbrick, 0, 2);
world.setBlock(i+10, j+13, k+4, MEBlocks.skeletonbrick, 0, 2);
world.setBlock(i+11, j+13, k+4, MEBlocks.skeletonbrick, 0, 2);
world.setBlock(i+12, j+13, k+4, MEBlocks.skeletonbrick, 0, 2);
world.setBlock(i+13, j+13, k+4, MEBlocks.skeletonbrick, 0, 2);
world.setBlock(i+3, j+13, k+5, MEBlocks.skeletonbrick, 0, 2);
world.setBlock(i+4, j+13, k+5, MEBlocks.skeletonbrick, 0, 2);
world.setBlock(i+5, j+13, k+5, MEBlocks.skeletonbrick, 0, 2);
world.setBlock(i+6, j+13, k+5, MEBlocks.skeletonbrick, 0, 2);
world.setBlock(i+7, j+13, k+5, MEBlocks.skeletonbrick, 0, 2);
world.setBlock(i+8, j+13, k+5, MEBlocks.skeletonbrick, 0, 2);
world.setBlock(i+9, j+13, k+5, MEBlocks.skeletonbrick, 0, 2);
world.setBlock(i+10, j+13, k+5, MEBlocks.skeletonbrick, 0, 2);
world.setBlock(i+11, j+13, k+5, MEBlocks.skeletonbrick, 0, 2);
world.setBlock(i+12, j+13, k+5, MEBlocks.skeletonbrick, 0, 2);
world.setBlock(i+13, j+13, k+5, MEBlocks.skeletonbrick, 0, 2);
world.setBlock(i+3, j+13, k+6, MEBlocks.skeletonbrick, 0, 2);
world.setBlock(i+4, j+13, k+6, MEBlocks.skeletonbrick, 0, 2);
world.setBlock(i+5, j+13, k+6, MEBlocks.skeletonbrick, 0, 2);
world.setBlock(i+6, j+13, k+6, MEBlocks.skeletonbrick, 0, 2);
world.setBlock(i+7, j+13, k+6, MEBlocks.skeletonbrick, 0, 2);
world.setBlock(i+8, j+13, k+6, MEBlocks.skeletonbrick, 0, 2);
world.setBlock(i+9, j+13, k+6, MEBlocks.skeletonbrick, 0, 2);
world.setBlock(i+10, j+13, k+6, MEBlocks.skeletonbrick, 0, 2);
world.setBlock(i+11, j+13, k+6, MEBlocks.skeletonbrick, 0, 2);
world.setBlock(i+12, j+13, k+6, MEBlocks.skeletonbrick, 0, 2);
world.setBlock(i+13, j+13, k+6, MEBlocks.skeletonbrick, 0, 2);
world.setBlock(i+3, j+13, k+7, MEBlocks.skeletonbrick, 0, 2);
world.setBlock(i+4, j+13, k+7, MEBlocks.skeletonbrick, 0, 2);
world.setBlock(i+5, j+13, k+7, MEBlocks.skeletonbrick, 0, 2);
world.setBlock(i+6, j+13, k+7, MEBlocks.skeletonbrick, 0, 2);
world.setBlock(i+7, j+13, k+7, MEBlocks.skeletonbrick, 0, 2);
world.setBlock(i+8, j+13, k+7, MEBlocks.skeletonbrick, 0, 2);
world.setBlock(i+9, j+13, k+7, MEBlocks.skeletonbrick, 0, 2);
world.setBlock(i+10, j+13, k+7, MEBlocks.skeletonbrick, 0, 2);
world.setBlock(i+11, j+13, k+7, MEBlocks.skeletonbrick, 0, 2);
world.setBlock(i+12, j+13, k+7, MEBlocks.skeletonbrick, 0, 2);
world.setBlock(i+13, j+13, k+7, MEBlocks.skeletonbrick, 0, 2);
world.setBlock(i+3, j+13, k+8, MEBlocks.skeletonbrick, 0, 2);
world.setBlock(i+4, j+13, k+8, MEBlocks.skeletonbrick, 0, 2);
world.setBlock(i+5, j+13, k+8, MEBlocks.skeletonbrick, 0, 2);
world.setBlock(i+6, j+13, k+8, MEBlocks.skeletonbrick, 0, 2);
world.setBlock(i+7, j+13, k+8, MEBlocks.skeletonbrick, 0, 2);
world.setBlock(i+8, j+13, k+8, MEBlocks.skeletonbrick, 0, 2);
world.setBlock(i+9, j+13, k+8, MEBlocks.skeletonbrick, 0, 2);
world.setBlock(i+10, j+13, k+8, MEBlocks.skeletonbrick, 0, 2);
world.setBlock(i+11, j+13, k+8, MEBlocks.skeletonbrick, 0, 2);
world.setBlock(i+12, j+13, k+8, MEBlocks.skeletonbrick, 0, 2);
world.setBlock(i+13, j+13, k+8, MEBlocks.skeletonbrick, 0, 2);
world.setBlock(i+3, j+13, k+9, MEBlocks.skeletonbrick, 0, 2);
world.setBlock(i+4, j+13, k+9, MEBlocks.skeletonbrick, 0, 2);
world.setBlock(i+5, j+13, k+9, MEBlocks.skeletonbrick, 0, 2);
world.setBlock(i+6, j+13, k+9, MEBlocks.skeletonbrick, 0, 2);
world.setBlock(i+7, j+13, k+9, MEBlocks.skeletonbrick, 0, 2);
world.setBlock(i+8, j+13, k+9, MEBlocks.skeletonbrick, 0, 2);
world.setBlock(i+9, j+13, k+9, Block.getBlockById(65), 2, 2);
world.setBlock(i+10, j+13, k+9, MEBlocks.skeletonbrick, 0, 2);
world.setBlock(i+11, j+13, k+9, MEBlocks.skeletonbrick, 0, 2);
world.setBlock(i+12, j+13, k+9, MEBlocks.skeletonbrick, 0, 2);
world.setBlock(i+13, j+13, k+9, MEBlocks.skeletonbrick, 0, 2);
world.setBlock(i+3, j+13, k+10, MEBlocks.skeletonbrick, 0, 2);
world.setBlock(i+4, j+13, k+10, MEBlocks.skeletonbrick, 0, 2);
world.setBlock(i+5, j+13, k+10, MEBlocks.skeletonbrick, 0, 2);
world.setBlock(i+6, j+13, k+10, MEBlocks.skeletonbrick, 0, 2);
world.setBlock(i+7, j+13, k+10, MEBlocks.skeletonbrick, 0, 2);
world.setBlock(i+8, j+13, k+10, MEBlocks.skeletonbrick, 0, 2);
world.setBlock(i+9, j+13, k+10, MEBlocks.skeletonbrick, 0, 2);
world.setBlock(i+10, j+13, k+10, MEBlocks.skeletonbrick, 0, 2);
world.setBlock(i+11, j+13, k+10, MEBlocks.skeletonbrick, 0, 2);
world.setBlock(i+12, j+13, k+10, MEBlocks.skeletonbrick, 0, 2);
world.setBlock(i+13, j+13, k+10, MEBlocks.skeletonbrick, 0, 2);
world.setBlock(i+3, j+14, k+1, MEBlocks.skeletonbrick, 0, 2);
world.setBlock(i+4, j+14, k+1, MEBlocks.skeletonbrick, 0, 2);
world.setBlock(i+5, j+14, k+1, MEBlocks.skeletonbrick, 0, 2);
world.setBlock(i+6, j+14, k+1, MEBlocks.skeletonbrick, 0, 2);
world.setBlock(i+7, j+14, k+1, MEBlocks.skeletonbrick, 0, 2);
world.setBlock(i+8, j+14, k+1, MEBlocks.skeletonbrick, 0, 2);
world.setBlock(i+9, j+14, k+1, MEBlocks.skeletonbrick, 0, 2);
world.setBlock(i+10, j+14, k+1, MEBlocks.skeletonbrick, 0, 2);
world.setBlock(i+11, j+14, k+1, MEBlocks.skeletonbrick, 0, 2);
world.setBlock(i+12, j+14, k+1, MEBlocks.skeletonbrick, 0, 2);
world.setBlock(i+13, j+14, k+1, MEBlocks.skeletonbrick, 0, 2);
world.setBlock(i+3, j+14, k+2, MEBlocks.skeletonbrick, 0, 2);
world.setBlock(i+4, j+14, k+2, Block.getBlockById(11), 0, 2);
world.setBlock(i+5, j+14, k+2, MEBlocks.skeletonbrick, 0, 2);
world.setBlock(i+6, j+14, k+2, MEBlocks.skeletonbrick, 0, 2);
world.setBlock(i+7, j+14, k+2, MEBlocks.skeletonbrick, 0, 2);
world.setBlock(i+8, j+14, k+2, MEBlocks.skeletonbrick, 0, 2);
world.setBlock(i+9, j+14, k+2, MEBlocks.skeletonbrick, 0, 2);
world.setBlock(i+10, j+14, k+2, MEBlocks.skeletonbrick, 0, 2);
world.setBlock(i+11, j+14, k+2, MEBlocks.skeletonbrick, 0, 2);
world.setBlock(i+12, j+14, k+2, Block.getBlockById(11), 0, 2);
world.setBlock(i+13, j+14, k+2, MEBlocks.skeletonbrick, 0, 2);
world.setBlock(i+3, j+14, k+3, MEBlocks.skeletonbrick, 0, 2);
world.setBlock(i+4, j+14, k+3, MEBlocks.skeletonbrick, 0, 2);
world.setBlock(i+5, j+14, k+3, MEBlocks.skeletonbrick, 0, 2);
world.setBlock(i+6, j+14, k+3, MEBlocks.skeletonbrick, 0, 2);
world.setBlock(i+7, j+14, k+3, MEBlocks.skeletonbrick, 0, 2);
world.setBlock(i+8, j+14, k+3, MEBlocks.skeletonbrick, 0, 2);
world.setBlock(i+9, j+14, k+3, MEBlocks.skeletonbrick, 0, 2);
world.setBlock(i+10, j+14, k+3, MEBlocks.skeletonbrick, 0, 2);
world.setBlock(i+11, j+14, k+3, MEBlocks.skeletonbrick, 0, 2);
world.setBlock(i+12, j+14, k+3, MEBlocks.skeletonbrick, 0, 2);
world.setBlock(i+13, j+14, k+3, MEBlocks.skeletonbrick, 0, 2);
world.setBlock(i+3, j+14, k+4, MEBlocks.skeletonbrick, 0, 2);
world.setBlock(i+4, j+14, k+4, MEBlocks.skeletonbrick, 0, 2);
world.setBlock(i+5, j+14, k+4, MEBlocks.skeletonbrick, 0, 2);
world.setBlock(i+6, j+14, k+4, MEBlocks.skeletonbrick, 0, 2);
world.setBlock(i+7, j+14, k+4, MEBlocks.skeletonbrick, 0, 2);
world.setBlock(i+8, j+14, k+4, MEBlocks.skeletonbrick, 0, 2);
world.setBlock(i+9, j+14, k+4, MEBlocks.skeletonbrick, 0, 2);
world.setBlock(i+10, j+14, k+4, MEBlocks.skeletonbrick, 0, 2);
world.setBlock(i+11, j+14, k+4, MEBlocks.skeletonbrick, 0, 2);
world.setBlock(i+12, j+14, k+4, MEBlocks.skeletonbrick, 0, 2);
world.setBlock(i+13, j+14, k+4, MEBlocks.skeletonbrick, 0, 2);
world.setBlock(i+3, j+14, k+5, MEBlocks.skeletonbrick, 0, 2);
world.setBlock(i+4, j+14, k+5, MEBlocks.skeletonbrick, 0, 2);
world.setBlock(i+5, j+14, k+5, MEBlocks.skeletonbrick, 0, 2);
world.setBlock(i+6, j+14, k+5, MEBlocks.skeletonbrick, 0, 2);
world.setBlock(i+7, j+14, k+5, MEBlocks.skeletonbrick, 0, 2);
world.setBlock(i+8, j+14, k+5, MEBlocks.skeletonbrick, 0, 2);
world.setBlock(i+9, j+14, k+5, MEBlocks.skeletonbrick, 0, 2);
world.setBlock(i+10, j+14, k+5, MEBlocks.skeletonbrick, 0, 2);
world.setBlock(i+11, j+14, k+5, MEBlocks.skeletonbrick, 0, 2);
world.setBlock(i+12, j+14, k+5, MEBlocks.skeletonbrick, 0, 2);
world.setBlock(i+13, j+14, k+5, MEBlocks.skeletonbrick, 0, 2);
world.setBlock(i+3, j+14, k+6, MEBlocks.skeletonbrick, 0, 2);
world.setBlock(i+4, j+14, k+6, MEBlocks.skeletonbrick, 0, 2);
world.setBlock(i+5, j+14, k+6, MEBlocks.skeletonbrick, 0, 2);
world.setBlock(i+6, j+14, k+6, MEBlocks.skeletonbrick, 0, 2);
world.setBlock(i+7, j+14, k+6, MEBlocks.skeletonbrick, 0, 2);
world.setBlock(i+8, j+14, k+6, MEBlocks.skeletonbrick, 0, 2);
world.setBlock(i+9, j+14, k+6, MEBlocks.skeletonbrick, 0, 2);
world.setBlock(i+10, j+14, k+6, MEBlocks.skeletonbrick, 0, 2);
world.setBlock(i+11, j+14, k+6, MEBlocks.skeletonbrick, 0, 2);
world.setBlock(i+12, j+14, k+6, MEBlocks.skeletonbrick, 0, 2);
world.setBlock(i+13, j+14, k+6, MEBlocks.skeletonbrick, 0, 2);
world.setBlock(i+3, j+14, k+7, MEBlocks.skeletonbrick, 0, 2);
world.setBlock(i+4, j+14, k+7, MEBlocks.skeletonbrick, 0, 2);
world.setBlock(i+5, j+14, k+7, MEBlocks.skeletonbrick, 0, 2);
world.setBlock(i+6, j+14, k+7, MEBlocks.skeletonbrick, 0, 2);
world.setBlock(i+7, j+14, k+7, MEBlocks.skeletonbrick, 0, 2);
world.setBlock(i+8, j+14, k+7, MEBlocks.skeletonbrick, 0, 2);
world.setBlock(i+9, j+14, k+7, MEBlocks.skeletonbrick, 0, 2);
world.setBlock(i+10, j+14, k+7, MEBlocks.skeletonbrick, 0, 2);
world.setBlock(i+11, j+14, k+7, MEBlocks.skeletonbrick, 0, 2);
world.setBlock(i+12, j+14, k+7, MEBlocks.skeletonbrick, 0, 2);
world.setBlock(i+13, j+14, k+7, MEBlocks.skeletonbrick, 0, 2);
world.setBlock(i+3, j+14, k+8, MEBlocks.skeletonbrick, 0, 2);
world.setBlock(i+4, j+14, k+8, MEBlocks.skeletonbrick, 0, 2);
world.setBlock(i+5, j+14, k+8, MEBlocks.skeletonbrick, 0, 2);
world.setBlock(i+6, j+14, k+8, MEBlocks.skeletonbrick, 0, 2);
world.setBlock(i+7, j+14, k+8, MEBlocks.skeletonbrick, 0, 2);
world.setBlock(i+8, j+14, k+8, MEBlocks.skeletonbrick, 0, 2);
world.setBlock(i+9, j+14, k+8, MEBlocks.skeletonbrick, 0, 2);
world.setBlock(i+10, j+14, k+8, MEBlocks.skeletonbrick, 0, 2);
world.setBlock(i+11, j+14, k+8, MEBlocks.skeletonbrick, 0, 2);
world.setBlock(i+12, j+14, k+8, MEBlocks.skeletonbrick, 0, 2);
world.setBlock(i+13, j+14, k+8, MEBlocks.skeletonbrick, 0, 2);
world.setBlock(i+3, j+14, k+9, MEBlocks.skeletonbrick, 0, 2);
world.setBlock(i+4, j+14, k+9, Block.getBlockById(11), 0, 2);
world.setBlock(i+5, j+14, k+9, MEBlocks.skeletonbrick, 0, 2);
world.setBlock(i+6, j+14, k+9, MEBlocks.skeletonbrick, 0, 2);
world.setBlock(i+7, j+14, k+9, MEBlocks.skeletonbrick, 0, 2);
world.setBlock(i+8, j+14, k+9, MEBlocks.skeletonbrick, 0, 2);
world.setBlock(i+9, j+14, k+9, Block.getBlockById(65), 2, 2);
world.setBlock(i+10, j+14, k+9, MEBlocks.skeletonbrick, 0, 2);
world.setBlock(i+11, j+14, k+9, MEBlocks.skeletonbrick, 0, 2);
world.setBlock(i+12, j+14, k+9, Block.getBlockById(11), 0, 2);
world.setBlock(i+13, j+14, k+9, MEBlocks.skeletonbrick, 0, 2);
world.setBlock(i+3, j+14, k+10, MEBlocks.skeletonbrick, 0, 2);
world.setBlock(i+4, j+14, k+10, MEBlocks.skeletonbrick, 0, 2);
world.setBlock(i+5, j+14, k+10, MEBlocks.skeletonbrick, 0, 2);
world.setBlock(i+6, j+14, k+10, MEBlocks.skeletonbrick, 0, 2);
world.setBlock(i+7, j+14, k+10, MEBlocks.skeletonbrick, 0, 2);
world.setBlock(i+8, j+14, k+10, MEBlocks.skeletonbrick, 0, 2);
world.setBlock(i+9, j+14, k+10, MEBlocks.skeletonbrick, 0, 2);
world.setBlock(i+10, j+14, k+10, MEBlocks.skeletonbrick, 0, 2);
world.setBlock(i+11, j+14, k+10, MEBlocks.skeletonbrick, 0, 2);
world.setBlock(i+12, j+14, k+10, MEBlocks.skeletonbrick, 0, 2);
world.setBlock(i+13, j+14, k+10, MEBlocks.skeletonbrick, 0, 2);
world.setBlock(i+3, j+15, k+1, MEBlocks.skeletonbrick, 0, 2);
world.setBlock(i+4, j+15, k+1, MEBlocks.skeletonbrick, 0, 2);
world.setBlock(i+5, j+15, k+1, MEBlocks.skeletonbrick, 0, 2);
world.setBlock(i+6, j+15, k+1, MEBlocks.skeletonbrick, 0, 2);
world.setBlock(i+7, j+15, k+1, MEBlocks.skeletonbrick, 0, 2);
world.setBlock(i+8, j+15, k+1, MEBlocks.skeletonbrick, 0, 2);
world.setBlock(i+9, j+15, k+1, MEBlocks.skeletonbrick, 0, 2);
world.setBlock(i+10, j+15, k+1, MEBlocks.skeletonbrick, 0, 2);
world.setBlock(i+11, j+15, k+1, MEBlocks.skeletonbrick, 0, 2);
world.setBlock(i+12, j+15, k+1, MEBlocks.skeletonbrick, 0, 2);
world.setBlock(i+13, j+15, k+1, MEBlocks.skeletonbrick, 0, 2);
world.setBlock(i+3, j+15, k+2, MEBlocks.skeletonbrick, 0, 2);
world.setBlock(i+5, j+15, k+2, MEBlocks.skeletonbrick, 0, 2);
world.setBlock(i+7, j+15, k+2, Block.getBlockById(25), 0, 2);
world.setBlock(i+8, j+15, k+2, Block.getBlockById(25), 0, 2);
world.setBlock(i+9, j+15, k+2, Block.getBlockById(65), 3, 2);
world.setBlock(i+11, j+15, k+2, MEBlocks.skeletonbrick, 0, 2);
world.setBlock(i+13, j+15, k+2, MEBlocks.skeletonbrick, 0, 2);
world.setBlock(i+3, j+15, k+3, MEBlocks.skeletonbrick, 0, 2);
world.setBlock(i+4, j+15, k+3, MEBlocks.skeletonbrick, 0, 2);
world.setBlock(i+12, j+15, k+3, MEBlocks.skeletonbrick, 0, 2);
world.setBlock(i+13, j+15, k+3, MEBlocks.skeletonbrick, 0, 2);
world.setBlock(i+3, j+15, k+4, MEBlocks.skeletonbrick, 0, 2);
world.setBlock(i+13, j+15, k+4, MEBlocks.skeletonbrick, 0, 2);
world.setBlock(i+3, j+15, k+5, MEBlocks.skeletonbrick, 0, 2);
world.setBlock(i+4, j+15, k+5, Block.getBlockById(25), 0, 2);
world.setBlock(i+12, j+15, k+5, Block.getBlockById(25), 0, 2);
world.setBlock(i+13, j+15, k+5, MEBlocks.skeletonbrick, 0, 2);
world.setBlock(i+3, j+15, k+6, MEBlocks.skeletonbrick, 0, 2);
world.setBlock(i+4, j+15, k+6, Block.getBlockById(25), 0, 2);
world.setBlock(i+12, j+15, k+6, Block.getBlockById(25), 0, 2);
world.setBlock(i+13, j+15, k+6, MEBlocks.skeletonbrick, 0, 2);
world.setBlock(i+3, j+15, k+7, MEBlocks.skeletonbrick, 0, 2);
world.setBlock(i+13, j+15, k+7, MEBlocks.skeletonbrick, 0, 2);
world.setBlock(i+3, j+15, k+8, MEBlocks.skeletonbrick, 0, 2);
world.setBlock(i+4, j+15, k+8, MEBlocks.skeletonbrick, 0, 2);
world.setBlock(i+12, j+15, k+8, MEBlocks.skeletonbrick, 0, 2);
world.setBlock(i+13, j+15, k+8, MEBlocks.skeletonbrick, 0, 2);
world.setBlock(i+3, j+15, k+9, MEBlocks.skeletonbrick, 0, 2);
world.setBlock(i+5, j+15, k+9, MEBlocks.skeletonbrick, 0, 2);
world.setBlock(i+11, j+15, k+9, MEBlocks.skeletonbrick, 0, 2);
world.setBlock(i+13, j+15, k+9, MEBlocks.skeletonbrick, 0, 2);
world.setBlock(i+3, j+15, k+10, MEBlocks.skeletonbrick, 0, 2);
world.setBlock(i+4, j+15, k+10, MEBlocks.skeletonbrick, 0, 2);
world.setBlock(i+5, j+15, k+10, MEBlocks.skeletonbrick, 0, 2);
world.setBlock(i+6, j+15, k+10, MEBlocks.skeletonbrick, 0, 2);
world.setBlock(i+7, j+15, k+10, MEBlocks.skeletonbrick, 0, 2);
world.setBlock(i+8, j+15, k+10, MEBlocks.skeletonbrick, 0, 2);
world.setBlock(i+9, j+15, k+10, MEBlocks.skeletonbrick, 0, 2);
world.setBlock(i+10, j+15, k+10, MEBlocks.skeletonbrick, 0, 2);
world.setBlock(i+11, j+15, k+10, MEBlocks.skeletonbrick, 0, 2);
world.setBlock(i+12, j+15, k+10, MEBlocks.skeletonbrick, 0, 2);
world.setBlock(i+13, j+15, k+10, MEBlocks.skeletonbrick, 0, 2);
world.setBlock(i+3, j+16, k+1, MEBlocks.skeletonbrick, 0, 2);
world.setBlock(i+4, j+16, k+1, MEBlocks.skeletonbrick, 0, 2);
world.setBlock(i+5, j+16, k+1, MEBlocks.skeletonbrick, 0, 2);
world.setBlock(i+6, j+16, k+1, MEBlocks.skeletonbrick, 0, 2);
world.setBlock(i+7, j+16, k+1, MEBlocks.skeletonbrick, 0, 2);
world.setBlock(i+8, j+16, k+1, MEBlocks.skeletonbrick, 0, 2);
world.setBlock(i+9, j+16, k+1, MEBlocks.skeletonbrick, 0, 2);
world.setBlock(i+10, j+16, k+1, MEBlocks.skeletonbrick, 0, 2);
world.setBlock(i+11, j+16, k+1, MEBlocks.skeletonbrick, 0, 2);
world.setBlock(i+12, j+16, k+1, MEBlocks.skeletonbrick, 0, 2);
world.setBlock(i+13, j+16, k+1, MEBlocks.skeletonbrick, 0, 2);
world.setBlock(i+3, j+16, k+2, MEBlocks.skeletonbrick, 0, 2);
world.setBlock(i+5, j+16, k+2, MEBlocks.skeletonbrick, 0, 2);
world.setBlock(i+9, j+16, k+2, Block.getBlockById(65), 3, 2);
world.setBlock(i+11, j+16, k+2, MEBlocks.skeletonbrick, 0, 2);
world.setBlock(i+13, j+16, k+2, MEBlocks.skeletonbrick, 0, 2);
world.setBlock(i+3, j+16, k+3, MEBlocks.skeletonbrick, 0, 2);
world.setBlock(i+4, j+16, k+3, MEBlocks.skeletonbrick, 0, 2);
world.setBlock(i+12, j+16, k+3, MEBlocks.skeletonbrick, 0, 2);
world.setBlock(i+13, j+16, k+3, MEBlocks.skeletonbrick, 0, 2);
world.setBlock(i+3, j+16, k+4, MEBlocks.skeletonbrick, 0, 2);
world.setBlock(i+13, j+16, k+4, MEBlocks.skeletonbrick, 0, 2);
world.setBlock(i+3, j+16, k+5, MEBlocks.skeletonbrick, 0, 2);
world.setBlock(i+13, j+16, k+5, MEBlocks.skeletonbrick, 0, 2);
world.setBlock(i+3, j+16, k+6, MEBlocks.skeletonbrick, 0, 2);
world.setBlock(i+13, j+16, k+6, MEBlocks.skeletonbrick, 0, 2);
world.setBlock(i+3, j+16, k+7, MEBlocks.skeletonbrick, 0, 2);
world.setBlock(i+13, j+16, k+7, MEBlocks.skeletonbrick, 0, 2);
world.setBlock(i+3, j+16, k+8, MEBlocks.skeletonbrick, 0, 2);
world.setBlock(i+4, j+16, k+8, MEBlocks.skeletonbrick, 0, 2);
world.setBlock(i+12, j+16, k+8, MEBlocks.skeletonbrick, 0, 2);
world.setBlock(i+13, j+16, k+8, MEBlocks.skeletonbrick, 0, 2);
world.setBlock(i+3, j+16, k+9, MEBlocks.skeletonbrick, 0, 2);
world.setBlock(i+5, j+16, k+9, MEBlocks.skeletonbrick, 0, 2);
world.setBlock(i+11, j+16, k+9, MEBlocks.skeletonbrick, 0, 2);
world.setBlock(i+13, j+16, k+9, MEBlocks.skeletonbrick, 0, 2);
world.setBlock(i+3, j+16, k+10, MEBlocks.skeletonbrick, 0, 2);
world.setBlock(i+4, j+16, k+10, MEBlocks.skeletonbrick, 0, 2);
world.setBlock(i+5, j+16, k+10, MEBlocks.skeletonbrick, 0, 2);
world.setBlock(i+6, j+16, k+10, MEBlocks.skeletonbrick, 0, 2);
world.setBlock(i+7, j+16, k+10, MEBlocks.skeletonbrick, 0, 2);
world.setBlock(i+8, j+16, k+10, MEBlocks.skeletonbrick, 0, 2);
world.setBlock(i+9, j+16, k+10, MEBlocks.skeletonbrick, 0, 2);
world.setBlock(i+10, j+16, k+10, MEBlocks.skeletonbrick, 0, 2);
world.setBlock(i+11, j+16, k+10, MEBlocks.skeletonbrick, 0, 2);
world.setBlock(i+12, j+16, k+10, MEBlocks.skeletonbrick, 0, 2);
world.setBlock(i+13, j+16, k+10, MEBlocks.skeletonbrick, 0, 2);
world.setBlock(i+3, j+17, k+1, MEBlocks.skeletonbrick, 0, 2);
world.setBlock(i+4, j+17, k+1, MEBlocks.skeletonbrick, 0, 2);
world.setBlock(i+5, j+17, k+1, MEBlocks.skeletonbrick, 0, 2);
world.setBlock(i+6, j+17, k+1, MEBlocks.skeletonbrick, 0, 2);
world.setBlock(i+7, j+17, k+1, MEBlocks.skeletonbrick, 0, 2);
world.setBlock(i+8, j+17, k+1, MEBlocks.skeletonbrick, 0, 2);
world.setBlock(i+9, j+17, k+1, MEBlocks.skeletonbrick, 0, 2);
world.setBlock(i+10, j+17, k+1, MEBlocks.skeletonbrick, 0, 2);
world.setBlock(i+11, j+17, k+1, MEBlocks.skeletonbrick, 0, 2);
world.setBlock(i+12, j+17, k+1, MEBlocks.skeletonbrick, 0, 2);
world.setBlock(i+13, j+17, k+1, MEBlocks.skeletonbrick, 0, 2);
world.setBlock(i+3, j+17, k+2, MEBlocks.skeletonbrick, 0, 2);
world.setBlock(i+5, j+17, k+2, MEBlocks.skeletonbrick, 0, 2);
world.setBlock(i+9, j+17, k+2, Block.getBlockById(65), 3, 2);
world.setBlock(i+11, j+17, k+2, MEBlocks.skeletonbrick, 0, 2);
world.setBlock(i+13, j+17, k+2, MEBlocks.skeletonbrick, 0, 2);
world.setBlock(i+3, j+17, k+3, MEBlocks.skeletonbrick, 0, 2);
world.setBlock(i+4, j+17, k+3, MEBlocks.skeletonbrick, 0, 2);
world.setBlock(i+12, j+17, k+3, MEBlocks.skeletonbrick, 0, 2);
world.setBlock(i+13, j+17, k+3, MEBlocks.skeletonbrick, 0, 2);
world.setBlock(i+3, j+17, k+4, MEBlocks.skeletonbrick, 0, 2);
world.setBlock(i+13, j+17, k+4, MEBlocks.skeletonbrick, 0, 2);
world.setBlock(i+3, j+17, k+5, MEBlocks.skeletonbrick, 0, 2);
world.setBlock(i+13, j+17, k+5, MEBlocks.skeletonbrick, 0, 2);
world.setBlock(i+3, j+17, k+6, MEBlocks.skeletonbrick, 0, 2);
world.setBlock(i+13, j+17, k+6, MEBlocks.skeletonbrick, 0, 2);
world.setBlock(i+3, j+17, k+7, MEBlocks.skeletonbrick, 0, 2);
world.setBlock(i+13, j+17, k+7, MEBlocks.skeletonbrick, 0, 2);
world.setBlock(i+3, j+17, k+8, MEBlocks.skeletonbrick, 0, 2);
world.setBlock(i+4, j+17, k+8, MEBlocks.skeletonbrick, 0, 2);
world.setBlock(i+12, j+17, k+8, MEBlocks.skeletonbrick, 0, 2);
world.setBlock(i+13, j+17, k+8, MEBlocks.skeletonbrick, 0, 2);
world.setBlock(i+3, j+17, k+9, MEBlocks.skeletonbrick, 0, 2);
world.setBlock(i+5, j+17, k+9, MEBlocks.skeletonbrick, 0, 2);
world.setBlock(i+11, j+17, k+9, MEBlocks.skeletonbrick, 0, 2);
world.setBlock(i+13, j+17, k+9, MEBlocks.skeletonbrick, 0, 2);
world.setBlock(i+3, j+17, k+10, MEBlocks.skeletonbrick, 0, 2);
world.setBlock(i+4, j+17, k+10, MEBlocks.skeletonbrick, 0, 2);
world.setBlock(i+5, j+17, k+10, MEBlocks.skeletonbrick, 0, 2);
world.setBlock(i+6, j+17, k+10, MEBlocks.skeletonbrick, 0, 2);
world.setBlock(i+7, j+17, k+10, MEBlocks.skeletonbrick, 0, 2);
world.setBlock(i+8, j+17, k+10, MEBlocks.skeletonbrick, 0, 2);
world.setBlock(i+9, j+17, k+10, MEBlocks.skeletonbrick, 0, 2);
world.setBlock(i+10, j+17, k+10, MEBlocks.skeletonbrick, 0, 2);
world.setBlock(i+11, j+17, k+10, MEBlocks.skeletonbrick, 0, 2);
world.setBlock(i+12, j+17, k+10, MEBlocks.skeletonbrick, 0, 2);
world.setBlock(i+13, j+17, k+10, MEBlocks.skeletonbrick, 0, 2);
world.setBlock(i+3, j+18, k+1, MEBlocks.skeletonbrick, 0, 2);
world.setBlock(i+4, j+18, k+1, MEBlocks.skeletonbrick, 0, 2);
world.setBlock(i+5, j+18, k+1, MEBlocks.skeletonbrick, 0, 2);
world.setBlock(i+6, j+18, k+1, MEBlocks.skeletonbrick, 0, 2);
world.setBlock(i+7, j+18, k+1, MEBlocks.skeletonbrick, 0, 2);
world.setBlock(i+8, j+18, k+1, MEBlocks.skeletonbrick, 0, 2);
world.setBlock(i+9, j+18, k+1, MEBlocks.skeletonbrick, 0, 2);
world.setBlock(i+10, j+18, k+1, MEBlocks.skeletonbrick, 0, 2);
world.setBlock(i+11, j+18, k+1, MEBlocks.skeletonbrick, 0, 2);
world.setBlock(i+12, j+18, k+1, MEBlocks.skeletonbrick, 0, 2);
world.setBlock(i+13, j+18, k+1, MEBlocks.skeletonbrick, 0, 2);
world.setBlock(i+3, j+18, k+2, MEBlocks.skeletonbrick, 0, 2);
world.setBlock(i+9, j+18, k+2, Block.getBlockById(65), 3, 2);
world.setBlock(i+13, j+18, k+2, MEBlocks.skeletonbrick, 0, 2);
world.setBlock(i+3, j+18, k+3, MEBlocks.skeletonbrick, 0, 2);
world.setBlock(i+13, j+18, k+3, MEBlocks.skeletonbrick, 0, 2);
world.setBlock(i+3, j+18, k+4, MEBlocks.skeletonbrick, 0, 2);
world.setBlock(i+13, j+18, k+4, MEBlocks.skeletonbrick, 0, 2);
world.setBlock(i+3, j+18, k+5, MEBlocks.skeletonbrick, 0, 2);
world.setBlock(i+13, j+18, k+5, MEBlocks.skeletonbrick, 0, 2);
world.setBlock(i+3, j+18, k+6, MEBlocks.skeletonbrick, 0, 2);
world.setBlock(i+13, j+18, k+6, MEBlocks.skeletonbrick, 0, 2);
world.setBlock(i+3, j+18, k+7, MEBlocks.skeletonbrick, 0, 2);
world.setBlock(i+13, j+18, k+7, MEBlocks.skeletonbrick, 0, 2);
world.setBlock(i+3, j+18, k+8, MEBlocks.skeletonbrick, 0, 2);
world.setBlock(i+13, j+18, k+8, MEBlocks.skeletonbrick, 0, 2);
world.setBlock(i+3, j+18, k+9, MEBlocks.skeletonbrick, 0, 2);
world.setBlock(i+13, j+18, k+9, MEBlocks.skeletonbrick, 0, 2);
world.setBlock(i+3, j+18, k+10, MEBlocks.skeletonbrick, 0, 2);
world.setBlock(i+4, j+18, k+10, MEBlocks.skeletonbrick, 0, 2);
world.setBlock(i+5, j+18, k+10, MEBlocks.skeletonbrick, 0, 2);
world.setBlock(i+6, j+18, k+10, MEBlocks.skeletonbrick, 0, 2);
world.setBlock(i+7, j+18, k+10, MEBlocks.skeletonbrick, 0, 2);
world.setBlock(i+8, j+18, k+10, MEBlocks.skeletonbrick, 0, 2);
world.setBlock(i+9, j+18, k+10, MEBlocks.skeletonbrick, 0, 2);
world.setBlock(i+10, j+18, k+10, MEBlocks.skeletonbrick, 0, 2);
world.setBlock(i+11, j+18, k+10, MEBlocks.skeletonbrick, 0, 2);
world.setBlock(i+12, j+18, k+10, MEBlocks.skeletonbrick, 0, 2);
world.setBlock(i+13, j+18, k+10, MEBlocks.skeletonbrick, 0, 2);
world.setBlock(i+3, j+19, k+1, MEBlocks.skeletonbrick, 0, 2);
world.setBlock(i+4, j+19, k+1, MEBlocks.skeletonbrick, 0, 2);
world.setBlock(i+5, j+19, k+1, MEBlocks.skeletonbrick, 0, 2);
world.setBlock(i+6, j+19, k+1, MEBlocks.skeletonbrick, 0, 2);
world.setBlock(i+7, j+19, k+1, MEBlocks.skeletonbrick, 0, 2);
world.setBlock(i+8, j+19, k+1, MEBlocks.skeletonbrick, 0, 2);
world.setBlock(i+9, j+19, k+1, MEBlocks.skeletonbrick, 0, 2);
world.setBlock(i+10, j+19, k+1, MEBlocks.skeletonbrick, 0, 2);
world.setBlock(i+11, j+19, k+1, MEBlocks.skeletonbrick, 0, 2);
world.setBlock(i+12, j+19, k+1, MEBlocks.skeletonbrick, 0, 2);
world.setBlock(i+13, j+19, k+1, MEBlocks.skeletonbrick, 0, 2);
world.setBlock(i+2, j+19, k+2, MEBlocks.skeletonbrick, 0, 2);
world.setBlock(i+3, j+19, k+2, MEBlocks.skeletonbrick, 0, 2);
world.setBlock(i+9, j+19, k+2, Block.getBlockById(65), 3, 2);
world.setBlock(i+13, j+19, k+2, MEBlocks.skeletonbrick, 0, 2);
world.setBlock(i+14, j+19, k+2, MEBlocks.skeletonbrick, 0, 2);
world.setBlock(i+2, j+19, k+3, MEBlocks.skeletonbrick, 0, 2);
world.setBlock(i+3, j+19, k+3, MEBlocks.skeletonbrick, 0, 2);
world.setBlock(i+13, j+19, k+3, MEBlocks.skeletonbrick, 0, 2);
world.setBlock(i+14, j+19, k+3, MEBlocks.skeletonbrick, 0, 2);
world.setBlock(i+2, j+19, k+4, MEBlocks.skeletonbrick, 0, 2);
world.setBlock(i+3, j+19, k+4, MEBlocks.skeletonbrick, 0, 2);
world.setBlock(i+13, j+19, k+4, MEBlocks.skeletonbrick, 0, 2);
world.setBlock(i+14, j+19, k+4, MEBlocks.skeletonbrick, 0, 2);
world.setBlock(i+2, j+19, k+5, MEBlocks.skeletonbrick, 0, 2);
world.setBlock(i+3, j+19, k+5, MEBlocks.skeletonbrick, 0, 2);
world.setBlock(i+13, j+19, k+5, MEBlocks.skeletonbrick, 0, 2);
world.setBlock(i+14, j+19, k+5, MEBlocks.skeletonbrick, 0, 2);
world.setBlock(i+2, j+19, k+6, MEBlocks.skeletonbrick, 0, 2);
world.setBlock(i+3, j+19, k+6, MEBlocks.skeletonbrick, 0, 2);
world.setBlock(i+13, j+19, k+6, MEBlocks.skeletonbrick, 0, 2);
world.setBlock(i+14, j+19, k+6, MEBlocks.skeletonbrick, 0, 2);
world.setBlock(i+2, j+19, k+7, MEBlocks.skeletonbrick, 0, 2);
world.setBlock(i+3, j+19, k+7, MEBlocks.skeletonbrick, 0, 2);
world.setBlock(i+13, j+19, k+7, MEBlocks.skeletonbrick, 0, 2);
world.setBlock(i+14, j+19, k+7, MEBlocks.skeletonbrick, 0, 2);
world.setBlock(i+2, j+19, k+8, MEBlocks.skeletonbrick, 0, 2);
world.setBlock(i+3, j+19, k+8, MEBlocks.skeletonbrick, 0, 2);
world.setBlock(i+13, j+19, k+8, MEBlocks.skeletonbrick, 0, 2);
world.setBlock(i+14, j+19, k+8, MEBlocks.skeletonbrick, 0, 2);
world.setBlock(i+2, j+19, k+9, MEBlocks.skeletonbrick, 0, 2);
world.setBlock(i+3, j+19, k+9, MEBlocks.skeletonbrick, 0, 2);
world.setBlock(i+13, j+19, k+9, MEBlocks.skeletonbrick, 0, 2);
world.setBlock(i+14, j+19, k+9, MEBlocks.skeletonbrick, 0, 2);
world.setBlock(i+2, j+19, k+10, MEBlocks.skeletonbrick, 0, 2);
world.setBlock(i+3, j+19, k+10, MEBlocks.skeletonbrick, 0, 2);
world.setBlock(i+4, j+19, k+10, MEBlocks.skeletonbrick, 0, 2);
world.setBlock(i+5, j+19, k+10, MEBlocks.skeletonbrick, 0, 2);
world.setBlock(i+6, j+19, k+10, MEBlocks.skeletonbrick, 0, 2);
world.setBlock(i+7, j+19, k+10, MEBlocks.skeletonbrick, 0, 2);
world.setBlock(i+8, j+19, k+10, MEBlocks.skeletonbrick, 0, 2);
world.setBlock(i+9, j+19, k+10, MEBlocks.skeletonbrick, 0, 2);
world.setBlock(i+10, j+19, k+10, MEBlocks.skeletonbrick, 0, 2);
world.setBlock(i+11, j+19, k+10, MEBlocks.skeletonbrick, 0, 2);
world.setBlock(i+12, j+19, k+10, MEBlocks.skeletonbrick, 0, 2);
world.setBlock(i+13, j+19, k+10, MEBlocks.skeletonbrick, 0, 2);
world.setBlock(i+14, j+19, k+10, MEBlocks.skeletonbrick, 0, 2);
world.setBlock(i+2, j+19, k+11, MEBlocks.skeletonbrick, 0, 2);
world.setBlock(i+14, j+19, k+11, MEBlocks.skeletonbrick, 0, 2);
world.setBlock(i+2, j+19, k+12, MEBlocks.skeletonbrick, 0, 2);
world.setBlock(i+3, j+19, k+12, MEBlocks.skeletonbrick, 0, 2);
world.setBlock(i+4, j+19, k+12, MEBlocks.skeletonbrick, 0, 2);
world.setBlock(i+5, j+19, k+12, MEBlocks.skeletonbrick, 0, 2);
world.setBlock(i+6, j+19, k+12, MEBlocks.skeletonbrick, 0, 2);
world.setBlock(i+7, j+19, k+12, MEBlocks.skeletonbrick, 0, 2);
world.setBlock(i+8, j+19, k+12, MEBlocks.skeletonbrick, 0, 2);
world.setBlock(i+9, j+19, k+12, MEBlocks.skeletonbrick, 0, 2);
world.setBlock(i+10, j+19, k+12, MEBlocks.skeletonbrick, 0, 2);
world.setBlock(i+11, j+19, k+12, MEBlocks.skeletonbrick, 0, 2);
world.setBlock(i+12, j+19, k+12, MEBlocks.skeletonbrick, 0, 2);
world.setBlock(i+13, j+19, k+12, MEBlocks.skeletonbrick, 0, 2);
world.setBlock(i+14, j+19, k+12, MEBlocks.skeletonbrick, 0, 2);
world.setBlock(i+1, j+20, k+1, MEBlocks.skeletonbrick, 0, 2);
world.setBlock(i+2, j+20, k+1, MEBlocks.skeletonbrick, 0, 2);
world.setBlock(i+3, j+20, k+1, MEBlocks.skeletonbrick, 0, 2);
world.setBlock(i+4, j+20, k+1, MEBlocks.skeletonbrick, 0, 2);
world.setBlock(i+5, j+20, k+1, MEBlocks.skeletonbrick, 0, 2);
world.setBlock(i+6, j+20, k+1, MEBlocks.skeletonbrick, 0, 2);
world.setBlock(i+7, j+20, k+1, MEBlocks.skeletonbrick, 0, 2);
world.setBlock(i+8, j+20, k+1, MEBlocks.skeletonbrick, 0, 2);
world.setBlock(i+9, j+20, k+1, MEBlocks.skeletonbrick, 0, 2);
world.setBlock(i+10, j+20, k+1, MEBlocks.skeletonbrick, 0, 2);
world.setBlock(i+11, j+20, k+1, MEBlocks.skeletonbrick, 0, 2);
world.setBlock(i+12, j+20, k+1, MEBlocks.skeletonbrick, 0, 2);
world.setBlock(i+13, j+20, k+1, MEBlocks.skeletonbrick, 0, 2);
world.setBlock(i+14, j+20, k+1, MEBlocks.skeletonbrick, 0, 2);
world.setBlock(i+15, j+20, k+1, MEBlocks.skeletonbrick, 0, 2);
world.setBlock(i+1, j+20, k+2, MEBlocks.skeletonbrick, 0, 2);
world.setBlock(i+2, j+20, k+2, Block.getBlockById(11), 10, 2);
world.setBlock(i+3, j+20, k+2, MEBlocks.skeletonbrick, 0, 2);
world.setBlock(i+4, j+20, k+2, MEBlocks.skeletonbrick, 0, 2);
world.setBlock(i+5, j+20, k+2, MEBlocks.skeletonbrick, 0, 2);
world.setBlock(i+6, j+20, k+2, MEBlocks.skeletonbrick, 0, 2);
world.setBlock(i+7, j+20, k+2, MEBlocks.skeletonbrick, 0, 2);
world.setBlock(i+8, j+20, k+2, MEBlocks.skeletonbrick, 0, 2);
world.setBlock(i+9, j+20, k+2, Block.getBlockById(65), 3, 2);//1234567890987655555555555555555555555551111111111116666662637222222222222
world.setBlock(i+10, j+20, k+2, MEBlocks.skeletonbrick, 0, 2);
world.setBlock(i+11, j+20, k+2, MEBlocks.skeletonbrick, 0, 2);
world.setBlock(i+12, j+20, k+2, MEBlocks.skeletonbrick, 0, 2);
world.setBlock(i+13, j+20, k+2, MEBlocks.skeletonbrick, 0, 2);
world.setBlock(i+14, j+20, k+2, Block.getBlockById(11), 10, 2);
world.setBlock(i+15, j+20, k+2, MEBlocks.skeletonbrick, 0, 2);
world.setBlock(i+1, j+20, k+3, MEBlocks.skeletonbrick, 0, 2);
world.setBlock(i+2, j+20, k+3, Block.getBlockById(11), 2, 2);
world.setBlock(i+3, j+20, k+3, MEBlocks.skeletonbrick, 0, 2);
world.setBlock(i+4, j+20, k+3, MEBlocks.skeletonbrick, 0, 2);
world.setBlock(i+5, j+20, k+3, MEBlocks.skeletonbrick, 0, 2);
world.setBlock(i+6, j+20, k+3, MEBlocks.skeletonbrick, 0, 2);
world.setBlock(i+7, j+20, k+3, MEBlocks.skeletonbrick, 0, 2);
world.setBlock(i+8, j+20, k+3, MEBlocks.skeletonbrick, 0, 2);
world.setBlock(i+9, j+20, k+3, MEBlocks.skeletonbrick, 0, 2);
world.setBlock(i+10, j+20, k+3, MEBlocks.skeletonbrick, 0, 2);
world.setBlock(i+11, j+20, k+3, MEBlocks.skeletonbrick, 0, 2);
world.setBlock(i+12, j+20, k+3, MEBlocks.skeletonbrick, 0, 2);
world.setBlock(i+13, j+20, k+3, MEBlocks.skeletonbrick, 0, 2);
world.setBlock(i+14, j+20, k+3, Block.getBlockById(11), 2, 2);
world.setBlock(i+15, j+20, k+3, MEBlocks.skeletonbrick, 0, 2);
world.setBlock(i+1, j+20, k+4, MEBlocks.skeletonbrick, 0, 2);
world.setBlock(i+2, j+20, k+4, Block.getBlockById(11), 4, 2);
world.setBlock(i+3, j+20, k+4, MEBlocks.skeletonbrick, 0, 2);
world.setBlock(i+4, j+20, k+4, MEBlocks.skeletonbrick, 0, 2);
world.setBlock(i+5, j+20, k+4, MEBlocks.skeletonbrick, 0, 2);
world.setBlock(i+6, j+20, k+4, MEBlocks.skeletonbrick, 0, 2);
world.setBlock(i+7, j+20, k+4, MEBlocks.skeletonbrick, 0, 2);
world.setBlock(i+8, j+20, k+4, MEBlocks.skeletonbrick, 0, 2);
world.setBlock(i+9, j+20, k+4, MEBlocks.skeletonbrick, 0, 2);
world.setBlock(i+10, j+20, k+4, MEBlocks.skeletonbrick, 0, 2);
world.setBlock(i+11, j+20, k+4, MEBlocks.skeletonbrick, 0, 2);
world.setBlock(i+12, j+20, k+4, MEBlocks.skeletonbrick, 0, 2);
world.setBlock(i+13, j+20, k+4, MEBlocks.skeletonbrick, 0, 2);
world.setBlock(i+14, j+20, k+4, Block.getBlockById(11), 4, 2);
world.setBlock(i+15, j+20, k+4, MEBlocks.skeletonbrick, 0, 2);
world.setBlock(i+1, j+20, k+5, MEBlocks.skeletonbrick, 0, 2);
world.setBlock(i+2, j+20, k+5, Block.getBlockById(11), 2, 2);
world.setBlock(i+3, j+20, k+5, MEBlocks.skeletonbrick, 0, 2);
world.setBlock(i+4, j+20, k+5, MEBlocks.skeletonbrick, 0, 2);
world.setBlock(i+5, j+20, k+5, MEBlocks.skeletonbrick, 0, 2);
world.setBlock(i+6, j+20, k+5, MEBlocks.skeletonbrick, 0, 2);
world.setBlock(i+7, j+20, k+5, MEBlocks.skeletonbrick, 0, 2);
world.setBlock(i+8, j+20, k+5, MEBlocks.skeletonbrick, 0, 2);
world.setBlock(i+9, j+20, k+5, MEBlocks.skeletonbrick, 0, 2);
world.setBlock(i+10, j+20, k+5, MEBlocks.skeletonbrick, 0, 2);
world.setBlock(i+11, j+20, k+5, MEBlocks.skeletonbrick, 0, 2);
world.setBlock(i+12, j+20, k+5, MEBlocks.skeletonbrick, 0, 2);
world.setBlock(i+13, j+20, k+5, MEBlocks.skeletonbrick, 0, 2);
world.setBlock(i+14, j+20, k+5, Block.getBlockById(11), 2, 2);
world.setBlock(i+15, j+20, k+5, MEBlocks.skeletonbrick, 0, 2);
world.setBlock(i+1, j+20, k+6, MEBlocks.skeletonbrick, 0, 2);
world.setBlock(i+2, j+20, k+6, Block.getBlockById(11), 10, 2);
world.setBlock(i+3, j+20, k+6, MEBlocks.skeletonbrick, 0, 2);
world.setBlock(i+4, j+20, k+6, MEBlocks.skeletonbrick, 0, 2);
world.setBlock(i+5, j+20, k+6, MEBlocks.skeletonbrick, 0, 2);
world.setBlock(i+6, j+20, k+6, MEBlocks.skeletonbrick, 0, 2);
world.setBlock(i+7, j+20, k+6, MEBlocks.skeletonbrick, 0, 2);
world.setBlock(i+8, j+20, k+6, MEBlocks.skeletonbrick, 0, 2);
world.setBlock(i+9, j+20, k+6, MEBlocks.skeletonbrick, 0, 2);
world.setBlock(i+10, j+20, k+6, MEBlocks.skeletonbrick, 0, 2);
world.setBlock(i+11, j+20, k+6, MEBlocks.skeletonbrick, 0, 2);
world.setBlock(i+12, j+20, k+6, MEBlocks.skeletonbrick, 0, 2);
world.setBlock(i+13, j+20, k+6, MEBlocks.skeletonbrick, 0, 2);
world.setBlock(i+14, j+20, k+6, Block.getBlockById(11), 10, 2);
world.setBlock(i+15, j+20, k+6, MEBlocks.skeletonbrick, 0, 2);
world.setBlock(i+1, j+20, k+7, MEBlocks.skeletonbrick, 0, 2);
world.setBlock(i+2, j+20, k+7, Block.getBlockById(11), 10, 2);
world.setBlock(i+3, j+20, k+7, MEBlocks.skeletonbrick, 0, 2);
world.setBlock(i+4, j+20, k+7, MEBlocks.skeletonbrick, 0, 2);
world.setBlock(i+5, j+20, k+7, MEBlocks.skeletonbrick, 0, 2);
world.setBlock(i+6, j+20, k+7, MEBlocks.skeletonbrick, 0, 2);
world.setBlock(i+7, j+20, k+7, MEBlocks.skeletonbrick, 0, 2);
world.setBlock(i+8, j+20, k+7, MEBlocks.skeletonbrick, 0, 2);
world.setBlock(i+9, j+20, k+7, MEBlocks.skeletonbrick, 0, 2);
world.setBlock(i+10, j+20, k+7, MEBlocks.skeletonbrick, 0, 2);
world.setBlock(i+11, j+20, k+7, MEBlocks.skeletonbrick, 0, 2);
world.setBlock(i+12, j+20, k+7, MEBlocks.skeletonbrick, 0, 2);
world.setBlock(i+13, j+20, k+7, MEBlocks.skeletonbrick, 0, 2);
world.setBlock(i+14, j+20, k+7, Block.getBlockById(11), 10, 2);
world.setBlock(i+15, j+20, k+7, MEBlocks.skeletonbrick, 0, 2);
world.setBlock(i+1, j+20, k+8, MEBlocks.skeletonbrick, 0, 2);
world.setBlock(i+2, j+20, k+8, Block.getBlockById(11), 2, 2);
world.setBlock(i+3, j+20, k+8, MEBlocks.skeletonbrick, 0, 2);
world.setBlock(i+4, j+20, k+8, MEBlocks.skeletonbrick, 0, 2);
world.setBlock(i+5, j+20, k+8, MEBlocks.skeletonbrick, 0, 2);
world.setBlock(i+6, j+20, k+8, MEBlocks.skeletonbrick, 0, 2);
world.setBlock(i+7, j+20, k+8, MEBlocks.skeletonbrick, 0, 2);
world.setBlock(i+8, j+20, k+8, MEBlocks.skeletonbrick, 0, 2);
world.setBlock(i+9, j+20, k+8, MEBlocks.skeletonbrick, 0, 2);
world.setBlock(i+10, j+20, k+8, MEBlocks.skeletonbrick, 0, 2);
world.setBlock(i+11, j+20, k+8, MEBlocks.skeletonbrick, 0, 2);
world.setBlock(i+12, j+20, k+8, MEBlocks.skeletonbrick, 0, 2);
world.setBlock(i+13, j+20, k+8, MEBlocks.skeletonbrick, 0, 2);
world.setBlock(i+14, j+20, k+8, Block.getBlockById(11), 2, 2);
world.setBlock(i+15, j+20, k+8, MEBlocks.skeletonbrick, 0, 2);
world.setBlock(i+1, j+20, k+9, MEBlocks.skeletonbrick, 0, 2);
world.setBlock(i+2, j+20, k+9, Block.getBlockById(11), 4, 2);
world.setBlock(i+3, j+20, k+9, MEBlocks.skeletonbrick, 0, 2);
world.setBlock(i+4, j+20, k+9, MEBlocks.skeletonbrick, 0, 2);
world.setBlock(i+5, j+20, k+9, MEBlocks.skeletonbrick, 0, 2);
world.setBlock(i+6, j+20, k+9, MEBlocks.skeletonbrick, 0, 2);
world.setBlock(i+7, j+20, k+9, MEBlocks.skeletonbrick, 0, 2);
world.setBlock(i+8, j+20, k+9, MEBlocks.skeletonbrick, 0, 2);
world.setBlock(i+9, j+20, k+9, MEBlocks.skeletonbrick, 0, 2);
world.setBlock(i+10, j+20, k+9, MEBlocks.skeletonbrick, 0, 2);
world.setBlock(i+11, j+20, k+9, MEBlocks.skeletonbrick, 0, 2);
world.setBlock(i+12, j+20, k+9, MEBlocks.skeletonbrick, 0, 2);
world.setBlock(i+13, j+20, k+9, MEBlocks.skeletonbrick, 0, 2);
world.setBlock(i+14, j+20, k+9, Block.getBlockById(11), 4, 2);
world.setBlock(i+15, j+20, k+9, MEBlocks.skeletonbrick, 0, 2);
world.setBlock(i+1, j+20, k+10, MEBlocks.skeletonbrick, 0, 2);
world.setBlock(i+2, j+20, k+10, Block.getBlockById(11), 4, 2);
world.setBlock(i+3, j+20, k+10, MEBlocks.skeletonbrick, 0, 2);
world.setBlock(i+4, j+20, k+10, MEBlocks.skeletonbrick, 0, 2);
world.setBlock(i+5, j+20, k+10, MEBlocks.skeletonbrick, 0, 2);
world.setBlock(i+6, j+20, k+10, MEBlocks.skeletonbrick, 0, 2);
world.setBlock(i+7, j+20, k+10, MEBlocks.skeletonbrick, 0, 2);
world.setBlock(i+8, j+20, k+10, MEBlocks.skeletonbrick, 0, 2);
world.setBlock(i+9, j+20, k+10, MEBlocks.skeletonbrick, 0, 2);
world.setBlock(i+10, j+20, k+10, MEBlocks.skeletonbrick, 0, 2);
world.setBlock(i+11, j+20, k+10, MEBlocks.skeletonbrick, 0, 2);
world.setBlock(i+12, j+20, k+10, MEBlocks.skeletonbrick, 0, 2);
world.setBlock(i+13, j+20, k+10, MEBlocks.skeletonbrick, 0, 2);
world.setBlock(i+14, j+20, k+10, Block.getBlockById(11), 4, 2);
world.setBlock(i+15, j+20, k+10, MEBlocks.skeletonbrick, 0, 2);
world.setBlock(i+1, j+20, k+11, MEBlocks.skeletonbrick, 0, 2);
world.setBlock(i+2, j+20, k+11, Block.getBlockById(11), 2, 2);
world.setBlock(i+3, j+20, k+11, MEBlocks.skeletonbrick, 0, 2);
world.setBlock(i+4, j+20, k+11, MEBlocks.skeletonbrick, 0, 2);
world.setBlock(i+5, j+20, k+11, MEBlocks.skeletonbrick, 0, 2);
world.setBlock(i+6, j+20, k+11, MEBlocks.skeletonbrick, 0, 2);
world.setBlock(i+7, j+20, k+11, MEBlocks.skeletonbrick, 0, 2);
world.setBlock(i+8, j+20, k+11, MEBlocks.skeletonbrick, 0, 2);
world.setBlock(i+9, j+20, k+11, MEBlocks.skeletonbrick, 0, 2);
world.setBlock(i+10, j+20, k+11, MEBlocks.skeletonbrick, 0, 2);
world.setBlock(i+11, j+20, k+11, MEBlocks.skeletonbrick, 0, 2);
world.setBlock(i+12, j+20, k+11, MEBlocks.skeletonbrick, 0, 2);
world.setBlock(i+13, j+20, k+11, MEBlocks.skeletonbrick, 0, 2);
world.setBlock(i+14, j+20, k+11, Block.getBlockById(11), 2, 2);
world.setBlock(i+15, j+20, k+11, MEBlocks.skeletonbrick, 0, 2);
world.setBlock(i+1, j+20, k+12, MEBlocks.skeletonbrick, 0, 2);
world.setBlock(i+2, j+20, k+12, Block.getBlockById(11), 10, 2);
world.setBlock(i+3, j+20, k+12, Block.getBlockById(11), 2, 2);
world.setBlock(i+4, j+20, k+12, Block.getBlockById(11), 4, 2);
world.setBlock(i+5, j+20, k+12, Block.getBlockById(11), 4, 2);
